Workbook

Sheet 거래처별요약
A1: 2026년 컴투스 매출현황 (게임매출 주요 거래처)
F2: (단위: 백만원)
A3: 분류 | B3: 거래처 | C3: 1월 | D3: 2월 | E3: 3월 | F3: 4월
A4: 게임매출 | B4: 애플 | C4: =IFERROR(SUMIFS(Raw_Data!$G:$G,Raw_Data!$AG:$AG,"애플",Raw_Data!$AH:$AH,"1월",Raw_Data!$AE:$AE,"게임매출")/1000000,0) -> 16546.202 | D4: =IFERROR(SUMIFS(Raw_Data!$G:$G,Raw_Data!$AG:$AG,"애플",Raw_Data!$AH:$AH,"2월",Raw_Data!$AE:$AE,"게임매출")/1000000,0) -> 17056.774 | E4: =IFERROR(SUMIFS(Raw_Data!$G:$G,Raw_Data!$AG:$AG,"애플",Raw_Data!$AH:$AH,"3월",Raw_Data!$AE:$AE,"게임매출")/1000000,0) -> 17717.311 | F4: =IFERROR(SUMIFS(Raw_Data!$G:$G,Raw_Data!$AG:$AG,"애플",Raw_Data!$AH:$AH,"4월",Raw_Data!$AE:$AE,"게임매출")/1000000,0) -> 19327.238
A5: 게임매출 | B5: 구글 | C5: =IFERROR(SUMIFS(Raw_Data!$G:$G,Raw_Data!$AG:$AG,"구글",Raw_Data!$AH:$AH,"1월",Raw_Data!$AE:$AE,"게임매출")/1000000,0) -> 13448.648 | D5: =IFERROR(SUMIFS(Raw_Data!$G:$G,Raw_Data!$AG:$AG,"구글",Raw_Data!$AH:$AH,"2월",Raw_Data!$AE:$AE,"게임매출")/1000000,0) -> 14419.718 | E5: =IFERROR(SUMIFS(Raw_Data!$G:$G,Raw_Data!$AG:$AG,"구글",Raw_Data!$AH:$AH,"3월",Raw_Data!$AE:$AE,"게임매출")/1000000,0) -> 13732.6 | F5: =IFERROR(SUMIFS(Raw_Data!$G:$G,Raw_Data!$AG:$AG,"구글",Raw_Data!$AH:$AH,"4월",Raw_Data!$AE:$AE,"게임매출")/1000000,0) -> 16225.337
A6: 게임매출 | B6: 원스토어 | C6: =IFERROR(SUMIFS(Raw_Data!$G:$G,Raw_Data!$AG:$AG,"원스토어",Raw_Data!$AH:$AH,"1월",Raw_Data!$AE:$AE,"게임매출")/1000000,0) -> 4431.6808 | D6: =IFERROR(SUMIFS(Raw_Data!$G:$G,Raw_Data!$AG:$AG,"원스토어",Raw_Data!$AH:$AH,"2월",Raw_Data!$AE:$AE,"게임매출")/1000000,0) -> 4397.6983 | E6: =IFERROR(SUMIFS(Raw_Data!$G:$G,Raw_Data!$AG:$AG,"원스토어",Raw_Data!$AH:$AH,"3월",Raw_Data!$AE:$AE,"게임매출")/1000000,0) -> 4309.0618 | F6: =IFERROR(SUMIFS(Raw_Data!$G:$G,Raw_Data!$AG:$AG,"원스토어",Raw_Data!$AH:$AH,"4월",Raw_Data!$AE:$AE,"게임매출")/1000000,0) -> 4384.1162
A7: 게임매출 | B7: Valve | C7: =IFERROR(SUMIFS(Raw_Data!$G:$G,Raw_Data!$AG:$AG,"Valve",Raw_Data!$AH:$AH,"1월",Raw_Data!$AE:$AE,"게임매출")/1000000,0) -> 1414.8924 | D7: =IFERROR(SUMIFS(Raw_Data!$G:$G,Raw_Data!$AG:$AG,"Valve",Raw_Data!$AH:$AH,"2월",Raw_Data!$AE:$AE,"게임매출")/1000000,0) -> 1434.907 | E7: =IFERROR(SUMIFS(Raw_Data!$G:$G,Raw_Data!$AG:$AG,"Valve",Raw_Data!$AH:$AH,"3월",Raw_Data!$AE:$AE,"게임매출")/1000000,0) -> 1229.9719 | F7: =IFERROR(SUMIFS(Raw_Data!$G:$G,Raw_Data!$AG:$AG,"Valve",Raw_Data!$AH:$AH,"4월",Raw_Data!$AE:$AE,"게임매출")/1000000,0) -> 1826.6024
A8: 게임매출 | B8: Huawei | C8: =IFERROR(SUMIFS(Raw_Data!$G:$G,Raw_Data!$AG:$AG,"Huawei",Raw_Data!$AH:$AH,"1월",Raw_Data!$AE:$AE,"게임매출")/1000000,0) -> 973.26369 | D8: =IFERROR(SUMIFS(Raw_Data!$G:$G,Raw_Data!$AG:$AG,"Huawei",Raw_Data!$AH:$AH,"2월",Raw_Data!$AE:$AE,"게임매출")/1000000,0) -> 979.56424 | E8: =IFERROR(SUMIFS(Raw_Data!$G:$G,Raw_Data!$AG:$AG,"Huawei",Raw_Data!$AH:$AH,"3월",Raw_Data!$AE:$AE,"게임매출")/1000000,0) -> 892.93406 | F8: =IFERROR(SUMIFS(Raw_Data!$G:$G,Raw_Data!$AG:$AG,"Huawei",Raw_Data!$AH:$AH,"4월",Raw_Data!$AE:$AE,"게임매출")/1000000,0) -> 1120.0215
A9: 게임매출 | B9: NHN | C9: =IFERROR(SUMIFS(Raw_Data!$G:$G,Raw_Data!$AG:$AG,"NHN",Raw_Data!$AH:$AH,"1월",Raw_Data!$AE:$AE,"게임매출")/1000000,0) -> 1176.7839 | D9: =IFERROR(SUMIFS(Raw_Data!$G:$G,Raw_Data!$AG:$AG,"NHN",Raw_Data!$AH:$AH,"2월",Raw_Data!$AE:$AE,"게임매출")/1000000,0) -> 1064.2218 | E9: =IFERROR(SUMIFS(Raw_Data!$G:$G,Raw_Data!$AG:$AG,"NHN",Raw_Data!$AH:$AH,"3월",Raw_Data!$AE:$AE,"게임매출")/1000000,0) -> 941.88882 | F9: =IFERROR(SUMIFS(Raw_Data!$G:$G,Raw_Data!$AG:$AG,"NHN",Raw_Data!$AH:$AH,"4월",Raw_Data!$AE:$AE,"게임매출")/1000000,0) -> 1159.0805
A10: 게임매출 | B10: Beijing Raymobile | C10: =IFERROR(SUMIFS(Raw_Data!$G:$G,Raw_Data!$AG:$AG,"Beijing Raymobile",Raw_Data!$AH:$AH,"1월",Raw_Data!$AE:$AE,"게임매출")/1000000,0) -> 772.26266 | D10: =IFERROR(SUMIFS(Raw_Data!$G:$G,Raw_Data!$AG:$AG,"Beijing Raymobile",Raw_Data!$AH:$AH,"2월",Raw_Data!$AE:$AE,"게임매출")/1000000,0) -> 755.33302 | E10: =IFERROR(SUMIFS(Raw_Data!$G:$G,Raw_Data!$AG:$AG,"Beijing Raymobile",Raw_Data!$AH:$AH,"3월",Raw_Data!$AE:$AE,"게임매출")/1000000,0) -> 514.30051 | F10: =IFERROR(SUMIFS(Raw_Data!$G:$G,Raw_Data!$AG:$AG,"Beijing Raymobile",Raw_Data!$AH:$AH,"4월",Raw_Data!$AE:$AE,"게임매출")/1000000,0) -> 660.38051
A11: 게임매출 | B11: 기타 | C11: =IFERROR((SUMIFS(Raw_Data!$G:$G,Raw_Data!$AH:$AH,"1월",Raw_Data!$AE:$AE,"게임매출")-(SUMIFS(Raw_Data!$G:$G,Raw_Data!$AG:$AG,"애플",Raw_Data!$AH:$AH,"1월",Raw_Data!$AE:$AE,"게임매출")+SUMIFS(Raw_Data!$G:$G,Raw_Data!$AG:$AG,"구글",Raw_Data!$AH:$AH,"1월",Raw_Data!$AE:$AE,"게임매출")+SUMIFS(Raw_Data!$G:$G,Raw_Data!$AG:$AG,"원스토어",Raw_Data!$AH:$AH,"1월",Raw_Data!$AE:$AE,"게임매출")+SUMIFS(Raw_Data!$G:$G,Raw_Data!$AG:$AG,"Valve",Raw_Data!$AH:$AH,"1월",Raw_Data!$AE:$AE,"게임매출")+SUMIFS(Raw_Data!$G:$G,Raw_Data!$AG:$AG,"Huawei",Raw_Data!$AH:$AH,"1월",Raw_Data!$AE:$AE,"게임매출")+SUMIFS(Raw_Data!$G:$G,Raw_Data!$AG:$AG,"NHN",Raw_Data!$AH:$AH,"1월",Raw_Data!$AE:$AE,"게임매출")+SUMIFS(Raw_Data!$G:$G,Raw_Data!$AG:$AG,"Beijing Raymobile",Raw_Data!$AH:$AH,"1월",Raw_Data!$AE:$AE,"게임매출")))/1000000,0) -> 1383.3479 | D11: =IFERROR((SUMIFS(Raw_Data!$G:$G,Raw_Data!$AH:$AH,"2월",Raw_Data!$AE:$AE,"게임매출")-(SUMIFS(Raw_Data!$G:$G,Raw_Data!$AG:$AG,"애플",Raw_Data!$AH:$AH,"2월",Raw_Data!$AE:$AE,"게임매출")+SUMIFS(Raw_Data!$G:$G,Raw_Data!$AG:$AG,"구글",Raw_Data!$AH:$AH,"2월",Raw_Data!$AE:$AE,"게임매출")+SUMIFS(Raw_Data!$G:$G,Raw_Data!$AG:$AG,"원스토어",Raw_Data!$AH:$AH,"2월",Raw_Data!$AE:$AE,"게임매출")+SUMIFS(Raw_Data!$G:$G,Raw_Data!$AG:$AG,"Valve",Raw_Data!$AH:$AH,"2월",Raw_Data!$AE:$AE,"게임매출")+SUMIFS(Raw_Data!$G:$G,Raw_Data!$AG:$AG,"Huawei",Raw_Data!$AH:$AH,"2월",Raw_Data!$AE:$AE,"게임매출")+SUMIFS(Raw_Data!$G:$G,Raw_Data!$AG:$AG,"NHN",Raw_Data!$AH:$AH,"2월",Raw_Data!$AE:$AE,"게임매출")+SUMIFS(Raw_Data!$G:$G,Raw_Data!$AG:$AG,"Beijing Raymobile",Raw_Data!$AH:$AH,"2월",Raw_Data!$AE:$AE,"게임매출")))/1000000,0) -> 1337.669 | E11: =IFERROR((SUMIFS(Raw_Data!$G:$G,Raw_Data!$AH:$AH,"3월",Raw_Data!$AE:$AE,"게임매출")-(SUMIFS(Raw_Data!$G:$G,Raw_Data!$AG:$AG,"애플",Raw_Data!$AH:$AH,"3월",Raw_Data!$AE:$AE,"게임매출")+SUMIFS(Raw_Data!$G:$G,Raw_Data!$AG:$AG,"구글",Raw_Data!$AH:$AH,"3월",Raw_Data!$AE:$AE,"게임매출")+SUMIFS(Raw_Data!$G:$G,Raw_Data!$AG:$AG,"원스토어",Raw_Data!$AH:$AH,"3월",Raw_Data!$AE:$AE,"게임매출")+SUMIFS(Raw_Data!$G:$G,Raw_Data!$AG:$AG,"Valve",Raw_Data!$AH:$AH,"3월",Raw_Data!$AE:$AE,"게임매출")+SUMIFS(Raw_Data!$G:$G,Raw_Data!$AG:$AG,"Huawei",Raw_Data!$AH:$AH,"3월",Raw_Data!$AE:$AE,"게임매출")+SUMIFS(Raw_Data!$G:$G,Raw_Data!$AG:$AG,"NHN",Raw_Data!$AH:$AH,"3월",Raw_Data!$AE:$AE,"게임매출")+SUMIFS(Raw_Data!$G:$G,Raw_Data!$AG:$AG,"Beijing Raymobile",Raw_Data!$AH:$AH,"3월",Raw_Data!$AE:$AE,"게임매출")))/1000000,0) -> 41.182653 | F11: =IFERROR((SUMIFS(Raw_Data!$G:$G,Raw_Data!$AH:$AH,"4월",Raw_Data!$AE:$AE,"게임매출")-(SUMIFS(Raw_Data!$G:$G,Raw_Data!$AG:$AG,"애플",Raw_Data!$AH:$AH,"4월",Raw_Data!$AE:$AE,"게임매출")+SUMIFS(Raw_Data!$G:$G,Raw_Data!$AG:$AG,"구글",Raw_Data!$AH:$AH,"4월",Raw_Data!$AE:$AE,"게임매출")+SUMIFS(Raw_Data!$G:$G,Raw_Data!$AG:$AG,"원스토어",Raw_Data!$AH:$AH,"4월",Raw_Data!$AE:$AE,"게임매출")+SUMIFS(Raw_Data!$G:$G,Raw_Data!$AG:$AG,"Valve",Raw_Data!$AH:$AH,"4월",Raw_Data!$AE:$AE,"게임매출")+SUMIFS(Raw_Data!$G:$G,Raw_Data!$AG:$AG,"Huawei",Raw_Data!$AH:$AH,"4월",Raw_Data!$AE:$AE,"게임매출")+SUMIFS(Raw_Data!$G:$G,Raw_Data!$AG:$AG,"NHN",Raw_Data!$AH:$AH,"4월",Raw_Data!$AE:$AE,"게임매출")+SUMIFS(Raw_Data!$G:$G,Raw_Data!$AG:$AG,"Beijing Raymobile",Raw_Data!$AH:$AH,"4월",Raw_Data!$AE:$AE,"게임매출")))/1000000,0) -> 2262.3318
A12: 게임매출 | B12: 합계 | C12: =IFERROR(SUMIFS(Raw_Data!$G:$G,Raw_Data!$AH:$AH,"1월",Raw_Data!$AE:$AE,"게임매출")/1000000,0) -> 40147.081 | D12: =IFERROR(SUMIFS(Raw_Data!$G:$G,Raw_Data!$AH:$AH,"2월",Raw_Data!$AE:$AE,"게임매출")/1000000,0) -> 41445.886 | E12: =IFERROR(SUMIFS(Raw_Data!$G:$G,Raw_Data!$AH:$AH,"3월",Raw_Data!$AE:$AE,"게임매출")/1000000,0) -> 39379.252 | F12: =IFERROR(SUMIFS(Raw_Data!$G:$G,Raw_Data!$AH:$AH,"4월",Raw_Data!$AE:$AE,"게임매출")/1000000,0) -> 46965.107
A13: 기타수익 | B13: 합계 | C13: =IFERROR(SUMIFS(Raw_Data!$G:$G,Raw_Data!$AH:$AH,"1월",Raw_Data!$AE:$AE,"기타수익")/1000000,0) -> 131.13568 | D13: =IFERROR(SUMIFS(Raw_Data!$G:$G,Raw_Data!$AH:$AH,"2월",Raw_Data!$AE:$AE,"기타수익")/1000000,0) -> 111.10873 | E13: =IFERROR(SUMIFS(Raw_Data!$G:$G,Raw_Data!$AH:$AH,"3월",Raw_Data!$AE:$AE,"기타수익")/1000000,0) -> 392.67082 | F13: =IFERROR(SUMIFS(Raw_Data!$G:$G,Raw_Data!$AH:$AH,"4월",Raw_Data!$AE:$AE,"기타수익")/1000000,0) -> 307.08951
A14: 용역수익 | B14: 합계 | C14: =IFERROR(SUMIFS(Raw_Data!$G:$G,Raw_Data!$AH:$AH,"1월",Raw_Data!$AE:$AE,"용역수익")/1000000,0) -> 407.36392 | D14: =IFERROR(SUMIFS(Raw_Data!$G:$G,Raw_Data!$AH:$AH,"2월",Raw_Data!$AE:$AE,"용역수익")/1000000,0) -> 395.97834 | E14: =IFERROR(SUMIFS(Raw_Data!$G:$G,Raw_Data!$AH:$AH,"3월",Raw_Data!$AE:$AE,"용역수익")/1000000,0) -> 380.01259 | F14: =IFERROR(SUMIFS(Raw_Data!$G:$G,Raw_Data!$AH:$AH,"4월",Raw_Data!$AE:$AE,"용역수익")/1000000,0) -> 370.6743
A15: 합계 | B15: 총계 | C15: =C12+C13+C14 -> 40685.58 | D15: =D12+D13+D14 -> 41952.973 | E15: =E12+E13+E14 -> 40151.935 | F15: =F12+F13+F14 -> 47642.871

Sheet 1월
A1: 2026년 1월 매출현황 | D1: (단위: 원)
A3: ■ 게임매출
A4: 구분 | B4: 거래처명 | C4: 금액 | D4: 비고
A5: 모바일 | B5: Amazon | C5: =SUMIFS(Raw_Data!$G:$G,Raw_Data!$AG:$AG,"Amazon",Raw_Data!$AH:$AH,"1월",Raw_Data!$AE:$AE,"게임매출",Raw_Data!$AF:$AF,"모바일") -> 2109600
A6: 모바일 | B6: Beijing Raymobile | C6: =SUMIFS(Raw_Data!$G:$G,Raw_Data!$AG:$AG,"Beijing Raymobile",Raw_Data!$AH:$AH,"1월",Raw_Data!$AE:$AE,"게임매출",Raw_Data!$AF:$AF,"모바일") -> 772262657
A7: 모바일 | B7: Huawei | C7: =SUMIFS(Raw_Data!$G:$G,Raw_Data!$AG:$AG,"Huawei",Raw_Data!$AH:$AH,"1월",Raw_Data!$AE:$AE,"게임매출",Raw_Data!$AF:$AF,"모바일") -> 973263687
A8: 모바일 | B8: Red River | C8: =SUMIFS(Raw_Data!$G:$G,Raw_Data!$AG:$AG,"Red River",Raw_Data!$AH:$AH,"1월",Raw_Data!$AE:$AE,"게임매출",Raw_Data!$AF:$AF,"모바일") -> 61304768
A9: 모바일 | B9: Xsolla | C9: =SUMIFS(Raw_Data!$G:$G,Raw_Data!$AG:$AG,"Xsolla",Raw_Data!$AH:$AH,"1월",Raw_Data!$AE:$AE,"게임매출",Raw_Data!$AF:$AF,"모바일") -> 18235403
A10: 모바일 | B10: 구글 | C10: =SUMIFS(Raw_Data!$G:$G,Raw_Data!$AG:$AG,"구글",Raw_Data!$AH:$AH,"1월",Raw_Data!$AE:$AE,"게임매출",Raw_Data!$AF:$AF,"모바일") -> 13448647565
A11: 모바일 | B11: 밸로프 | C11: =SUMIFS(Raw_Data!$G:$G,Raw_Data!$AG:$AG,"밸로프",Raw_Data!$AH:$AH,"1월",Raw_Data!$AE:$AE,"게임매출",Raw_Data!$AF:$AF,"모바일") -> 1510368
A12: 모바일 | B12: 비바리퍼블리카 | C12: =SUMIFS(Raw_Data!$G:$G,Raw_Data!$AG:$AG,"비바리퍼블리카",Raw_Data!$AH:$AH,"1월",Raw_Data!$AE:$AE,"게임매출",Raw_Data!$AF:$AF,"모바일") -> 478182
A13: 모바일 | B13: 애플 | C13: =SUMIFS(Raw_Data!$G:$G,Raw_Data!$AG:$AG,"애플",Raw_Data!$AH:$AH,"1월",Raw_Data!$AE:$AE,"게임매출",Raw_Data!$AF:$AF,"모바일") -> 16546201961
A14: 모바일 | B14: 원스토어 | C14: =SUMIFS(Raw_Data!$G:$G,Raw_Data!$AG:$AG,"원스토어",Raw_Data!$AH:$AH,"1월",Raw_Data!$AE:$AE,"게임매출",Raw_Data!$AF:$AF,"모바일") -> 4431680760 | D14: ← 원스토어
A15: 모바일 | B15: 컴투스(수익이연) | C15: =SUMIFS(Raw_Data!$G:$G,Raw_Data!$AG:$AG,"컴투스(수익이연)",Raw_Data!$AH:$AH,"1월",Raw_Data!$AE:$AE,"게임매출",Raw_Data!$AF:$AF,"모바일") -> 0
A16: 모바일 | B16: 컴투스플랫폼 | C16: =SUMIFS(Raw_Data!$G:$G,Raw_Data!$AG:$AG,"컴투스플랫폼",Raw_Data!$AH:$AH,"1월",Raw_Data!$AE:$AE,"게임매출",Raw_Data!$AF:$AF,"모바일") -> 0
A17: 모바일 | B17: 컴투스홀딩스 | C17: =SUMIFS(Raw_Data!$G:$G,Raw_Data!$AG:$AG,"컴투스홀딩스",Raw_Data!$AH:$AH,"1월",Raw_Data!$AE:$AE,"게임매출",Raw_Data!$AF:$AF,"모바일") -> 35347414
A18: 온라인 | B18: NHN | C18: =SUMIFS(Raw_Data!$G:$G,Raw_Data!$AG:$AG,"NHN",Raw_Data!$AH:$AH,"1월",Raw_Data!$AE:$AE,"게임매출",Raw_Data!$AF:$AF,"온라인") -> 1176783913
A19: 온라인 | B19: Paypal | C19: =SUMIFS(Raw_Data!$G:$G,Raw_Data!$AG:$AG,"Paypal",Raw_Data!$AH:$AH,"1월",Raw_Data!$AE:$AE,"게임매출",Raw_Data!$AF:$AF,"온라인") -> 582427
A20: 온라인 | B20: SOFT-WORLD | C20: =SUMIFS(Raw_Data!$G:$G,Raw_Data!$AG:$AG,"SOFT-WORLD",Raw_Data!$AH:$AH,"1월",Raw_Data!$AE:$AE,"게임매출",Raw_Data!$AF:$AF,"온라인") -> 19795399 | D20: ← 스타시드 관련 (대만/HK 카드 매출)
A21: 온라인 | B21: Terminal3 | C21: =SUMIFS(Raw_Data!$G:$G,Raw_Data!$AG:$AG,"Terminal3",Raw_Data!$AH:$AH,"1월",Raw_Data!$AE:$AE,"게임매출",Raw_Data!$AF:$AF,"온라인") -> 9837996
A22: 온라인 | B22: Valve | C22: =SUMIFS(Raw_Data!$G:$G,Raw_Data!$AG:$AG,"Valve",Raw_Data!$AH:$AH,"1월",Raw_Data!$AE:$AE,"게임매출",Raw_Data!$AF:$AF,"온라인") -> 1414892374
A23: 온라인 | B23: 네이버파이낸셜 | C23: =SUMIFS(Raw_Data!$G:$G,Raw_Data!$AG:$AG,"네이버파이낸셜",Raw_Data!$AH:$AH,"1월",Raw_Data!$AE:$AE,"게임매출",Raw_Data!$AF:$AF,"온라인") -> 793948548
A24: 온라인 | B24: 토스페이먼츠 | C24: =SUMIFS(Raw_Data!$G:$G,Raw_Data!$AG:$AG,"토스페이먼츠",Raw_Data!$AH:$AH,"1월",Raw_Data!$AE:$AE,"게임매출",Raw_Data!$AF:$AF,"온라인") -> 219536364
A25: 광고 | B25: Admob | C25: =SUMIFS(Raw_Data!$G:$G,Raw_Data!$AG:$AG,"Admob",Raw_Data!$AH:$AH,"1월",Raw_Data!$AE:$AE,"게임매출",Raw_Data!$AF:$AF,"광고") -> 44
A26: 광고 | B26: Facebook | C26: =SUMIFS(Raw_Data!$G:$G,Raw_Data!$AG:$AG,"Facebook",Raw_Data!$AH:$AH,"1월",Raw_Data!$AE:$AE,"게임매출",Raw_Data!$AF:$AF,"광고") -> 15729274
A27: 광고 | B27: Line | C27: =SUMIFS(Raw_Data!$G:$G,Raw_Data!$AG:$AG,"Line",Raw_Data!$AH:$AH,"1월",Raw_Data!$AE:$AE,"게임매출",Raw_Data!$AF:$AF,"광고") -> 6795
A28: 광고 | B28: 넵튠 | C28: =SUMIFS(Raw_Data!$G:$G,Raw_Data!$AG:$AG,"넵튠",Raw_Data!$AH:$AH,"1월",Raw_Data!$AE:$AE,"게임매출",Raw_Data!$AF:$AF,"광고") -> 85697519 | D28: ← 러쉬 Xsolla 정산
A29: 광고 | B29: 원스토어(광고) | C29: =SUMIFS(Raw_Data!$G:$G,Raw_Data!$AG:$AG,"원스토어(광고)",Raw_Data!$AH:$AH,"1월",Raw_Data!$AE:$AE,"게임매출",Raw_Data!$AF:$AF,"광고") -> 117693060 | D29: ← 애드엑스플러스 사명 변경 (23.11)
A30: OOTP | B30: OOTP | C30: =SUMIFS(Raw_Data!$G:$G,Raw_Data!$AG:$AG,"OOTP",Raw_Data!$AH:$AH,"1월",Raw_Data!$AE:$AE,"게임매출",Raw_Data!$AF:$AF,"OOTP") -> 1534725 | D30: ← OOTP 관련(추정손익 파일상 기타매출로 분류)
A31: 모바일 소계 | C31: =SUM(C5:C17) -> 36291042365
A32: 온라인 소계 | C32: =SUM(C18:C24) -> 3635377021
A33: 광고 소계 | C33: =SUM(C25:C29) -> 219126692
A34: OOTP 소계 | C34: =SUM(C30:C30) -> 1534725
A35: 게임매출 합계 | C35: =C31+C32+C33+C34 -> 40147080803
A37: ■ 기타수익
A38: 구분 | B38: 거래처명 | C38: 금액 | D38: 비고
A39: 로열티수익 | B39: Moye Technology | C39: =SUMIFS(Raw_Data!$G:$G,Raw_Data!$AG:$AG,"Moye Technology",Raw_Data!$AH:$AH,"1월",Raw_Data!$AE:$AE,"기타수익",Raw_Data!$AF:$AF,"로열티수익") -> 0
A40: 로열티수익 | B40: OOTP(로열티) | C40: =SUMIFS(Raw_Data!$G:$G,Raw_Data!$AG:$AG,"OOTP(로열티)",Raw_Data!$AH:$AH,"1월",Raw_Data!$AE:$AE,"기타수익",Raw_Data!$AF:$AF,"로열티수익") -> 0
A41: 로열티수익 | B41: Skybound | C41: =SUMIFS(Raw_Data!$G:$G,Raw_Data!$AG:$AG,"Skybound",Raw_Data!$AH:$AH,"1월",Raw_Data!$AE:$AE,"기타수익",Raw_Data!$AF:$AF,"로열티수익") -> 0
A42: 로열티수익 | B42: 공게임즈 | C42: =SUMIFS(Raw_Data!$G:$G,Raw_Data!$AG:$AG,"공게임즈",Raw_Data!$AH:$AH,"1월",Raw_Data!$AE:$AE,"기타수익",Raw_Data!$AF:$AF,"로열티수익") -> 989829
...

Sheet 2월
A1: 2026년 2월 매출현황 | D1: (단위: 원)
A3: ■ 게임매출
A4: 구분 | B4: 거래처명 | C4: 금액 | D4: 비고
A5: 모바일 | B5: Amazon | C5: =SUMIFS(Raw_Data!$G:$G,Raw_Data!$AG:$AG,"Amazon",Raw_Data!$AH:$AH,"2월",Raw_Data!$AE:$AE,"게임매출",Raw_Data!$AF:$AF,"모바일") -> 28352245
A6: 모바일 | B6: Beijing Raymobile | C6: =SUMIFS(Raw_Data!$G:$G,Raw_Data!$AG:$AG,"Beijing Raymobile",Raw_Data!$AH:$AH,"2월",Raw_Data!$AE:$AE,"게임매출",Raw_Data!$AF:$AF,"모바일") -> 755333023
A7: 모바일 | B7: Huawei | C7: =SUMIFS(Raw_Data!$G:$G,Raw_Data!$AG:$AG,"Huawei",Raw_Data!$AH:$AH,"2월",Raw_Data!$AE:$AE,"게임매출",Raw_Data!$AF:$AF,"모바일") -> 979564244
A8: 모바일 | B8: Red River | C8: =SUMIFS(Raw_Data!$G:$G,Raw_Data!$AG:$AG,"Red River",Raw_Data!$AH:$AH,"2월",Raw_Data!$AE:$AE,"게임매출",Raw_Data!$AF:$AF,"모바일") -> 62213076
A9: 모바일 | B9: Xsolla | C9: =SUMIFS(Raw_Data!$G:$G,Raw_Data!$AG:$AG,"Xsolla",Raw_Data!$AH:$AH,"2월",Raw_Data!$AE:$AE,"게임매출",Raw_Data!$AF:$AF,"모바일") -> 18196314
A10: 모바일 | B10: 구글 | C10: =SUMIFS(Raw_Data!$G:$G,Raw_Data!$AG:$AG,"구글",Raw_Data!$AH:$AH,"2월",Raw_Data!$AE:$AE,"게임매출",Raw_Data!$AF:$AF,"모바일") -> 14419718224
A11: 모바일 | B11: 밸로프 | C11: =SUMIFS(Raw_Data!$G:$G,Raw_Data!$AG:$AG,"밸로프",Raw_Data!$AH:$AH,"2월",Raw_Data!$AE:$AE,"게임매출",Raw_Data!$AF:$AF,"모바일") -> 31623075
A12: 모바일 | B12: 비바리퍼블리카 | C12: =SUMIFS(Raw_Data!$G:$G,Raw_Data!$AG:$AG,"비바리퍼블리카",Raw_Data!$AH:$AH,"2월",Raw_Data!$AE:$AE,"게임매출",Raw_Data!$AF:$AF,"모바일") -> 225000
A13: 모바일 | B13: 애플 | C13: =SUMIFS(Raw_Data!$G:$G,Raw_Data!$AG:$AG,"애플",Raw_Data!$AH:$AH,"2월",Raw_Data!$AE:$AE,"게임매출",Raw_Data!$AF:$AF,"모바일") -> 17056774480
A14: 모바일 | B14: 원스토어 | C14: =SUMIFS(Raw_Data!$G:$G,Raw_Data!$AG:$AG,"원스토어",Raw_Data!$AH:$AH,"2월",Raw_Data!$AE:$AE,"게임매출",Raw_Data!$AF:$AF,"모바일") -> 4397698340 | D14: ← 원스토어
A15: 모바일 | B15: 컴투스(수익이연) | C15: =SUMIFS(Raw_Data!$G:$G,Raw_Data!$AG:$AG,"컴투스(수익이연)",Raw_Data!$AH:$AH,"2월",Raw_Data!$AE:$AE,"게임매출",Raw_Data!$AF:$AF,"모바일") -> 0
A16: 모바일 | B16: 컴투스플랫폼 | C16: =SUMIFS(Raw_Data!$G:$G,Raw_Data!$AG:$AG,"컴투스플랫폼",Raw_Data!$AH:$AH,"2월",Raw_Data!$AE:$AE,"게임매출",Raw_Data!$AF:$AF,"모바일") -> 0
A17: 모바일 | B17: 컴투스홀딩스 | C17: =SUMIFS(Raw_Data!$G:$G,Raw_Data!$AG:$AG,"컴투스홀딩스",Raw_Data!$AH:$AH,"2월",Raw_Data!$AE:$AE,"게임매출",Raw_Data!$AF:$AF,"모바일") -> 29677546
A18: 온라인 | B18: NHN | C18: =SUMIFS(Raw_Data!$G:$G,Raw_Data!$AG:$AG,"NHN",Raw_Data!$AH:$AH,"2월",Raw_Data!$AE:$AE,"게임매출",Raw_Data!$AF:$AF,"온라인") -> 1064221823
A19: 온라인 | B19: Paypal | C19: =SUMIFS(Raw_Data!$G:$G,Raw_Data!$AG:$AG,"Paypal",Raw_Data!$AH:$AH,"2월",Raw_Data!$AE:$AE,"게임매출",Raw_Data!$AF:$AF,"온라인") -> 534735
A20: 온라인 | B20: SOFT-WORLD | C20: =SUMIFS(Raw_Data!$G:$G,Raw_Data!$AG:$AG,"SOFT-WORLD",Raw_Data!$AH:$AH,"2월",Raw_Data!$AE:$AE,"게임매출",Raw_Data!$AF:$AF,"온라인") -> 0
A21: 온라인 | B21: Terminal3 | C21: =SUMIFS(Raw_Data!$G:$G,Raw_Data!$AG:$AG,"Terminal3",Raw_Data!$AH:$AH,"2월",Raw_Data!$AE:$AE,"게임매출",Raw_Data!$AF:$AF,"온라인") -> 13859338
A22: 온라인 | B22: Valve | C22: =SUMIFS(Raw_Data!$G:$G,Raw_Data!$AG:$AG,"Valve",Raw_Data!$AH:$AH,"2월",Raw_Data!$AE:$AE,"게임매출",Raw_Data!$AF:$AF,"온라인") -> 1434907028
A23: 온라인 | B23: 네이버파이낸셜 | C23: =SUMIFS(Raw_Data!$G:$G,Raw_Data!$AG:$AG,"네이버파이낸셜",Raw_Data!$AH:$AH,"2월",Raw_Data!$AE:$AE,"게임매출",Raw_Data!$AF:$AF,"온라인") -> 757668092
A24: 온라인 | B24: 토스페이먼츠 | C24: =SUMIFS(Raw_Data!$G:$G,Raw_Data!$AG:$AG,"토스페이먼츠",Raw_Data!$AH:$AH,"2월",Raw_Data!$AE:$AE,"게임매출",Raw_Data!$AF:$AF,"온라인") -> 183753182
A25: 광고 | B25: Admob | C25: =SUMIFS(Raw_Data!$G:$G,Raw_Data!$AG:$AG,"Admob",Raw_Data!$AH:$AH,"2월",Raw_Data!$AE:$AE,"게임매출",Raw_Data!$AF:$AF,"광고") -> 0
A26: 광고 | B26: Facebook | C26: =SUMIFS(Raw_Data!$G:$G,Raw_Data!$AG:$AG,"Facebook",Raw_Data!$AH:$AH,"2월",Raw_Data!$AE:$AE,"게임매출",Raw_Data!$AF:$AF,"광고") -> 17306910
A27: 광고 | B27: Line | C27: =SUMIFS(Raw_Data!$G:$G,Raw_Data!$AG:$AG,"Line",Raw_Data!$AH:$AH,"2월",Raw_Data!$AE:$AE,"게임매출",Raw_Data!$AF:$AF,"광고") -> 2751
A28: 광고 | B28: 넵튠 | C28: =SUMIFS(Raw_Data!$G:$G,Raw_Data!$AG:$AG,"넵튠",Raw_Data!$AH:$AH,"2월",Raw_Data!$AE:$AE,"게임매출",Raw_Data!$AF:$AF,"광고") -> 71388096 | D28: ← 러쉬 Xsolla 정산
A29: 광고 | B29: 원스토어(광고) | C29: =SUMIFS(Raw_Data!$G:$G,Raw_Data!$AG:$AG,"원스토어(광고)",Raw_Data!$AH:$AH,"2월",Raw_Data!$AE:$AE,"게임매출",Raw_Data!$AF:$AF,"광고") -> 122140711 | D29: ← 애드엑스플러스 사명 변경 (23.11)
A30: OOTP | B30: OOTP | C30: =SUMIFS(Raw_Data!$G:$G,Raw_Data!$AG:$AG,"OOTP",Raw_Data!$AH:$AH,"2월",Raw_Data!$AE:$AE,"게임매출",Raw_Data!$AF:$AF,"OOTP") -> 727921 | D30: ← OOTP 관련(추정손익 파일상 기타매출로 분류)
A31: 모바일 소계 | C31: =SUM(C5:C17) -> 37779375567
A32: 온라인 소계 | C32: =SUM(C18:C24) -> 3454944198
A33: 광고 소계 | C33: =SUM(C25:C29) -> 210838468
A34: OOTP 소계 | C34: =SUM(C30:C30) -> 727921
A35: 게임매출 합계 | C35: =C31+C32+C33+C34 -> 41445886154
A37: ■ 기타수익
A38: 구분 | B38: 거래처명 | C38: 금액 | D38: 비고
A39: 로열티수익 | B39: Moye Technology | C39: =SUMIFS(Raw_Data!$G:$G,Raw_Data!$AG:$AG,"Moye Technology",Raw_Data!$AH:$AH,"2월",Raw_Data!$AE:$AE,"기타수익",Raw_Data!$AF:$AF,"로열티수익") -> 0
A40: 로열티수익 | B40: OOTP(로열티) | C40: =SUMIFS(Raw_Data!$G:$G,Raw_Data!$AG:$AG,"OOTP(로열티)",Raw_Data!$AH:$AH,"2월",Raw_Data!$AE:$AE,"기타수익",Raw_Data!$AF:$AF,"로열티수익") -> 0
A41: 로열티수익 | B41: Skybound | C41: =SUMIFS(Raw_Data!$G:$G,Raw_Data!$AG:$AG,"Skybound",Raw_Data!$AH:$AH,"2월",Raw_Data!$AE:$AE,"기타수익",Raw_Data!$AF:$AF,"로열티수익") -> 0
A42: 로열티수익 | B42: 공게임즈 | C42: =SUMIFS(Raw_Data!$G:$G,Raw_Data!$AG:$AG,"공게임즈",Raw_Data!$AH:$AH,"2월",Raw_Data!$AE:$AE,"기타수익",Raw_Data!$AF:$AF,"로열티수익") -> 0
...

Sheet 3월
A1: 2026년 3월 매출현황 | D1: (단위: 원)
A3: ■ 게임매출
A4: 구분 | B4: 거래처명 | C4: 금액 | D4: 비고
A5: 모바일 | B5: Amazon | C5: =SUMIFS(Raw_Data!$G:$G,Raw_Data!$AG:$AG,"Amazon",Raw_Data!$AH:$AH,"3월",Raw_Data!$AE:$AE,"게임매출",Raw_Data!$AF:$AF,"모바일") -> 24332100
A6: 모바일 | B6: Beijing Raymobile | C6: =SUMIFS(Raw_Data!$G:$G,Raw_Data!$AG:$AG,"Beijing Raymobile",Raw_Data!$AH:$AH,"3월",Raw_Data!$AE:$AE,"게임매출",Raw_Data!$AF:$AF,"모바일") -> 514300513
A7: 모바일 | B7: Huawei | C7: =SUMIFS(Raw_Data!$G:$G,Raw_Data!$AG:$AG,"Huawei",Raw_Data!$AH:$AH,"3월",Raw_Data!$AE:$AE,"게임매출",Raw_Data!$AF:$AF,"모바일") -> 892934056
A8: 모바일 | B8: Red River | C8: =SUMIFS(Raw_Data!$G:$G,Raw_Data!$AG:$AG,"Red River",Raw_Data!$AH:$AH,"3월",Raw_Data!$AE:$AE,"게임매출",Raw_Data!$AF:$AF,"모바일") -> 86513528
A9: 모바일 | B9: Xsolla | C9: =SUMIFS(Raw_Data!$G:$G,Raw_Data!$AG:$AG,"Xsolla",Raw_Data!$AH:$AH,"3월",Raw_Data!$AE:$AE,"게임매출",Raw_Data!$AF:$AF,"모바일") -> 227048611
A10: 모바일 | B10: 구글 | C10: =SUMIFS(Raw_Data!$G:$G,Raw_Data!$AG:$AG,"구글",Raw_Data!$AH:$AH,"3월",Raw_Data!$AE:$AE,"게임매출",Raw_Data!$AF:$AF,"모바일") -> 13732600499
A11: 모바일 | B11: 밸로프 | C11: =SUMIFS(Raw_Data!$G:$G,Raw_Data!$AG:$AG,"밸로프",Raw_Data!$AH:$AH,"3월",Raw_Data!$AE:$AE,"게임매출",Raw_Data!$AF:$AF,"모바일") -> 1308148
A12: 모바일 | B12: 비바리퍼블리카 | C12: =SUMIFS(Raw_Data!$G:$G,Raw_Data!$AG:$AG,"비바리퍼블리카",Raw_Data!$AH:$AH,"3월",Raw_Data!$AE:$AE,"게임매출",Raw_Data!$AF:$AF,"모바일") -> 56728
A13: 모바일 | B13: 애플 | C13: =SUMIFS(Raw_Data!$G:$G,Raw_Data!$AG:$AG,"애플",Raw_Data!$AH:$AH,"3월",Raw_Data!$AE:$AE,"게임매출",Raw_Data!$AF:$AF,"모바일") -> 17717311450
A14: 모바일 | B14: 원스토어 | C14: =SUMIFS(Raw_Data!$G:$G,Raw_Data!$AG:$AG,"원스토어",Raw_Data!$AH:$AH,"3월",Raw_Data!$AE:$AE,"게임매출",Raw_Data!$AF:$AF,"모바일") -> 4309061787 | D14: ← 원스토어
A15: 모바일 | B15: 컴투스(수익이연) | C15: =SUMIFS(Raw_Data!$G:$G,Raw_Data!$AG:$AG,"컴투스(수익이연)",Raw_Data!$AH:$AH,"3월",Raw_Data!$AE:$AE,"게임매출",Raw_Data!$AF:$AF,"모바일") -> -2120629176 | D15: ← K-IFRS 수익이연
A16: 모바일 | B16: 컴투스플랫폼 | C16: =SUMIFS(Raw_Data!$G:$G,Raw_Data!$AG:$AG,"컴투스플랫폼",Raw_Data!$AH:$AH,"3월",Raw_Data!$AE:$AE,"게임매출",Raw_Data!$AF:$AF,"모바일") -> 0
A17: 모바일 | B17: 컴투스홀딩스 | C17: =SUMIFS(Raw_Data!$G:$G,Raw_Data!$AG:$AG,"컴투스홀딩스",Raw_Data!$AH:$AH,"3월",Raw_Data!$AE:$AE,"게임매출",Raw_Data!$AF:$AF,"모바일") -> 19862221
A18: 온라인 | B18: NHN | C18: =SUMIFS(Raw_Data!$G:$G,Raw_Data!$AG:$AG,"NHN",Raw_Data!$AH:$AH,"3월",Raw_Data!$AE:$AE,"게임매출",Raw_Data!$AF:$AF,"온라인") -> 941888821
A19: 온라인 | B19: Paypal | C19: =SUMIFS(Raw_Data!$G:$G,Raw_Data!$AG:$AG,"Paypal",Raw_Data!$AH:$AH,"3월",Raw_Data!$AE:$AE,"게임매출",Raw_Data!$AF:$AF,"온라인") -> 30514809
A20: 온라인 | B20: SOFT-WORLD | C20: =SUMIFS(Raw_Data!$G:$G,Raw_Data!$AG:$AG,"SOFT-WORLD",Raw_Data!$AH:$AH,"3월",Raw_Data!$AE:$AE,"게임매출",Raw_Data!$AF:$AF,"온라인") -> 496335782 | D20: ← 스타시드 관련 (대만/HK 카드 매출)
A21: 온라인 | B21: Terminal3 | C21: =SUMIFS(Raw_Data!$G:$G,Raw_Data!$AG:$AG,"Terminal3",Raw_Data!$AH:$AH,"3월",Raw_Data!$AE:$AE,"게임매출",Raw_Data!$AF:$AF,"온라인") -> 61819697
A22: 온라인 | B22: Valve | C22: =SUMIFS(Raw_Data!$G:$G,Raw_Data!$AG:$AG,"Valve",Raw_Data!$AH:$AH,"3월",Raw_Data!$AE:$AE,"게임매출",Raw_Data!$AF:$AF,"온라인") -> 1229971944
A23: 온라인 | B23: 네이버파이낸셜 | C23: =SUMIFS(Raw_Data!$G:$G,Raw_Data!$AG:$AG,"네이버파이낸셜",Raw_Data!$AH:$AH,"3월",Raw_Data!$AE:$AE,"게임매출",Raw_Data!$AF:$AF,"온라인") -> 794956638
A24: 온라인 | B24: 토스페이먼츠 | C24: =SUMIFS(Raw_Data!$G:$G,Raw_Data!$AG:$AG,"토스페이먼츠",Raw_Data!$AH:$AH,"3월",Raw_Data!$AE:$AE,"게임매출",Raw_Data!$AF:$AF,"온라인") -> 112311727
A25: 광고 | B25: Admob | C25: =SUMIFS(Raw_Data!$G:$G,Raw_Data!$AG:$AG,"Admob",Raw_Data!$AH:$AH,"3월",Raw_Data!$AE:$AE,"게임매출",Raw_Data!$AF:$AF,"광고") -> 59
A26: 광고 | B26: Facebook | C26: =SUMIFS(Raw_Data!$G:$G,Raw_Data!$AG:$AG,"Facebook",Raw_Data!$AH:$AH,"3월",Raw_Data!$AE:$AE,"게임매출",Raw_Data!$AF:$AF,"광고") -> 20082886
A27: 광고 | B27: Line | C27: =SUMIFS(Raw_Data!$G:$G,Raw_Data!$AG:$AG,"Line",Raw_Data!$AH:$AH,"3월",Raw_Data!$AE:$AE,"게임매출",Raw_Data!$AF:$AF,"광고") -> 1218
A28: 광고 | B28: 넵튠 | C28: =SUMIFS(Raw_Data!$G:$G,Raw_Data!$AG:$AG,"넵튠",Raw_Data!$AH:$AH,"3월",Raw_Data!$AE:$AE,"게임매출",Raw_Data!$AF:$AF,"광고") -> 93064277 | D28: ← 러쉬 Xsolla 정산
A29: 광고 | B29: 원스토어(광고) | C29: =SUMIFS(Raw_Data!$G:$G,Raw_Data!$AG:$AG,"원스토어(광고)",Raw_Data!$AH:$AH,"3월",Raw_Data!$AE:$AE,"게임매출",Raw_Data!$AF:$AF,"광고") -> 187105772 | D29: ← 애드엑스플러스 사명 변경 (23.11)
A30: OOTP | B30: OOTP | C30: =SUMIFS(Raw_Data!$G:$G,Raw_Data!$AG:$AG,"OOTP",Raw_Data!$AH:$AH,"3월",Raw_Data!$AE:$AE,"게임매출",Raw_Data!$AF:$AF,"OOTP") -> 6497628 | D30: ← OOTP 관련(추정손익 파일상 기타매출로 분류)
A31: 모바일 소계 | C31: =SUM(C5:C17) -> 35404700465
A32: 온라인 소계 | C32: =SUM(C18:C24) -> 3667799418
A33: 광고 소계 | C33: =SUM(C25:C29) -> 300254212
A34: OOTP 소계 | C34: =SUM(C30:C30) -> 6497628
A35: 게임매출 합계 | C35: =C31+C32+C33+C34 -> 39379251723
A37: ■ 기타수익
A38: 구분 | B38: 거래처명 | C38: 금액 | D38: 비고
A39: 로열티수익 | B39: Moye Technology | C39: =SUMIFS(Raw_Data!$G:$G,Raw_Data!$AG:$AG,"Moye Technology",Raw_Data!$AH:$AH,"3월",Raw_Data!$AE:$AE,"기타수익",Raw_Data!$AF:$AF,"로열티수익") -> 0
A40: 로열티수익 | B40: OOTP(로열티) | C40: =SUMIFS(Raw_Data!$G:$G,Raw_Data!$AG:$AG,"OOTP(로열티)",Raw_Data!$AH:$AH,"3월",Raw_Data!$AE:$AE,"기타수익",Raw_Data!$AF:$AF,"로열티수익") -> 0
A41: 로열티수익 | B41: Skybound | C41: =SUMIFS(Raw_Data!$G:$G,Raw_Data!$AG:$AG,"Skybound",Raw_Data!$AH:$AH,"3월",Raw_Data!$AE:$AE,"기타수익",Raw_Data!$AF:$AF,"로열티수익") -> 0
A42: 로열티수익 | B42: 공게임즈 | C42: =SUMIFS(Raw_Data!$G:$G,Raw_Data!$AG:$AG,"공게임즈",Raw_Data!$AH:$AH,"3월",Raw_Data!$AE:$AE,"기타수익",Raw_Data!$AF:$AF,"로열티수익") -> 38159602
...

Sheet 4월
A1: 2026년 4월 매출현황 | D1: (단위: 원)
A3: ■ 게임매출
A4: 구분 | B4: 거래처명 | C4: 금액 | D4: 비고
A5: 모바일 | B5: Amazon | C5: =SUMIFS(Raw_Data!$G:$G,Raw_Data!$AG:$AG,"Amazon",Raw_Data!$AH:$AH,"4월",Raw_Data!$AE:$AE,"게임매출",Raw_Data!$AF:$AF,"모바일") -> 22927202
A6: 모바일 | B6: Beijing Raymobile | C6: =SUMIFS(Raw_Data!$G:$G,Raw_Data!$AG:$AG,"Beijing Raymobile",Raw_Data!$AH:$AH,"4월",Raw_Data!$AE:$AE,"게임매출",Raw_Data!$AF:$AF,"모바일") -> 660380514
A7: 모바일 | B7: Huawei | C7: =SUMIFS(Raw_Data!$G:$G,Raw_Data!$AG:$AG,"Huawei",Raw_Data!$AH:$AH,"4월",Raw_Data!$AE:$AE,"게임매출",Raw_Data!$AF:$AF,"모바일") -> 1120021474
A8: 모바일 | B8: Red River | C8: =SUMIFS(Raw_Data!$G:$G,Raw_Data!$AG:$AG,"Red River",Raw_Data!$AH:$AH,"4월",Raw_Data!$AE:$AE,"게임매출",Raw_Data!$AF:$AF,"모바일") -> -47832803
A9: 모바일 | B9: Xsolla | C9: =SUMIFS(Raw_Data!$G:$G,Raw_Data!$AG:$AG,"Xsolla",Raw_Data!$AH:$AH,"4월",Raw_Data!$AE:$AE,"게임매출",Raw_Data!$AF:$AF,"모바일") -> 303164011
A10: 모바일 | B10: 구글 | C10: =SUMIFS(Raw_Data!$G:$G,Raw_Data!$AG:$AG,"구글",Raw_Data!$AH:$AH,"4월",Raw_Data!$AE:$AE,"게임매출",Raw_Data!$AF:$AF,"모바일") -> 16225336835
A11: 모바일 | B11: 밸로프 | C11: =SUMIFS(Raw_Data!$G:$G,Raw_Data!$AG:$AG,"밸로프",Raw_Data!$AH:$AH,"4월",Raw_Data!$AE:$AE,"게임매출",Raw_Data!$AF:$AF,"모바일") -> 1662927
A12: 모바일 | B12: 비바리퍼블리카 | C12: =SUMIFS(Raw_Data!$G:$G,Raw_Data!$AG:$AG,"비바리퍼블리카",Raw_Data!$AH:$AH,"4월",Raw_Data!$AE:$AE,"게임매출",Raw_Data!$AF:$AF,"모바일") -> 13637
A13: 모바일 | B13: 애플 | C13: =SUMIFS(Raw_Data!$G:$G,Raw_Data!$AG:$AG,"애플",Raw_Data!$AH:$AH,"4월",Raw_Data!$AE:$AE,"게임매출",Raw_Data!$AF:$AF,"모바일") -> 19327237511
A14: 모바일 | B14: 원스토어 | C14: =SUMIFS(Raw_Data!$G:$G,Raw_Data!$AG:$AG,"원스토어",Raw_Data!$AH:$AH,"4월",Raw_Data!$AE:$AE,"게임매출",Raw_Data!$AF:$AF,"모바일") -> 4384116240 | D14: ← 원스토어
A15: 모바일 | B15: 컴투스(수익이연) | C15: =SUMIFS(Raw_Data!$G:$G,Raw_Data!$AG:$AG,"컴투스(수익이연)",Raw_Data!$AH:$AH,"4월",Raw_Data!$AE:$AE,"게임매출",Raw_Data!$AF:$AF,"모바일") -> 0
A16: 모바일 | B16: 컴투스플랫폼 | C16: =SUMIFS(Raw_Data!$G:$G,Raw_Data!$AG:$AG,"컴투스플랫폼",Raw_Data!$AH:$AH,"4월",Raw_Data!$AE:$AE,"게임매출",Raw_Data!$AF:$AF,"모바일") -> 0
A17: 모바일 | B17: 컴투스홀딩스 | C17: =SUMIFS(Raw_Data!$G:$G,Raw_Data!$AG:$AG,"컴투스홀딩스",Raw_Data!$AH:$AH,"4월",Raw_Data!$AE:$AE,"게임매출",Raw_Data!$AF:$AF,"모바일") -> 32651198
A18: 온라인 | B18: NHN | C18: =SUMIFS(Raw_Data!$G:$G,Raw_Data!$AG:$AG,"NHN",Raw_Data!$AH:$AH,"4월",Raw_Data!$AE:$AE,"게임매출",Raw_Data!$AF:$AF,"온라인") -> 1159080458
A19: 온라인 | B19: Paypal | C19: =SUMIFS(Raw_Data!$G:$G,Raw_Data!$AG:$AG,"Paypal",Raw_Data!$AH:$AH,"4월",Raw_Data!$AE:$AE,"게임매출",Raw_Data!$AF:$AF,"온라인") -> 67063986
A20: 온라인 | B20: SOFT-WORLD | C20: =SUMIFS(Raw_Data!$G:$G,Raw_Data!$AG:$AG,"SOFT-WORLD",Raw_Data!$AH:$AH,"4월",Raw_Data!$AE:$AE,"게임매출",Raw_Data!$AF:$AF,"온라인") -> 592031049 | D20: ← 스타시드 관련 (대만/HK 카드 매출)
A21: 온라인 | B21: Terminal3 | C21: =SUMIFS(Raw_Data!$G:$G,Raw_Data!$AG:$AG,"Terminal3",Raw_Data!$AH:$AH,"4월",Raw_Data!$AE:$AE,"게임매출",Raw_Data!$AF:$AF,"온라인") -> 77328946
A22: 온라인 | B22: Valve | C22: =SUMIFS(Raw_Data!$G:$G,Raw_Data!$AG:$AG,"Valve",Raw_Data!$AH:$AH,"4월",Raw_Data!$AE:$AE,"게임매출",Raw_Data!$AF:$AF,"온라인") -> 1826602402
A23: 온라인 | B23: 네이버파이낸셜 | C23: =SUMIFS(Raw_Data!$G:$G,Raw_Data!$AG:$AG,"네이버파이낸셜",Raw_Data!$AH:$AH,"4월",Raw_Data!$AE:$AE,"게임매출",Raw_Data!$AF:$AF,"온라인") -> 845488184
A24: 온라인 | B24: 토스페이먼츠 | C24: =SUMIFS(Raw_Data!$G:$G,Raw_Data!$AG:$AG,"토스페이먼츠",Raw_Data!$AH:$AH,"4월",Raw_Data!$AE:$AE,"게임매출",Raw_Data!$AF:$AF,"온라인") -> 113787364
A25: 광고 | B25: Admob | C25: =SUMIFS(Raw_Data!$G:$G,Raw_Data!$AG:$AG,"Admob",Raw_Data!$AH:$AH,"4월",Raw_Data!$AE:$AE,"게임매출",Raw_Data!$AF:$AF,"광고") -> 0
A26: 광고 | B26: Facebook | C26: =SUMIFS(Raw_Data!$G:$G,Raw_Data!$AG:$AG,"Facebook",Raw_Data!$AH:$AH,"4월",Raw_Data!$AE:$AE,"게임매출",Raw_Data!$AF:$AF,"광고") -> 18579569
A27: 광고 | B27: Line | C27: =SUMIFS(Raw_Data!$G:$G,Raw_Data!$AG:$AG,"Line",Raw_Data!$AH:$AH,"4월",Raw_Data!$AE:$AE,"게임매출",Raw_Data!$AF:$AF,"광고") -> 6285
A28: 광고 | B28: 넵튠 | C28: =SUMIFS(Raw_Data!$G:$G,Raw_Data!$AG:$AG,"넵튠",Raw_Data!$AH:$AH,"4월",Raw_Data!$AE:$AE,"게임매출",Raw_Data!$AF:$AF,"광고") -> 85241491 | D28: ← 러쉬 Xsolla 정산
A29: 광고 | B29: 원스토어(광고) | C29: =SUMIFS(Raw_Data!$G:$G,Raw_Data!$AG:$AG,"원스토어(광고)",Raw_Data!$AH:$AH,"4월",Raw_Data!$AE:$AE,"게임매출",Raw_Data!$AF:$AF,"광고") -> 146940773 | D29: ← 애드엑스플러스 사명 변경 (23.11)
A30: OOTP | B30: OOTP | C30: =SUMIFS(Raw_Data!$G:$G,Raw_Data!$AG:$AG,"OOTP",Raw_Data!$AH:$AH,"4월",Raw_Data!$AE:$AE,"게임매출",Raw_Data!$AF:$AF,"OOTP") -> 3278000 | D30: ← OOTP 관련(추정손익 파일상 기타매출로 분류)
A31: 모바일 소계 | C31: =SUM(C5:C17) -> 42029678746
A32: 온라인 소계 | C32: =SUM(C18:C24) -> 4681382389
A33: 광고 소계 | C33: =SUM(C25:C29) -> 250768118
A34: OOTP 소계 | C34: =SUM(C30:C30) -> 3278000
A35: 게임매출 합계 | C35: =C31+C32+C33+C34 -> 46965107253
A37: ■ 기타수익
A38: 구분 | B38: 거래처명 | C38: 금액 | D38: 비고
A39: 로열티수익 | B39: Moye Technology | C39: =SUMIFS(Raw_Data!$G:$G,Raw_Data!$AG:$AG,"Moye Technology",Raw_Data!$AH:$AH,"4월",Raw_Data!$AE:$AE,"기타수익",Raw_Data!$AF:$AF,"로열티수익") -> 0
A40: 로열티수익 | B40: OOTP(로열티) | C40: =SUMIFS(Raw_Data!$G:$G,Raw_Data!$AG:$AG,"OOTP(로열티)",Raw_Data!$AH:$AH,"4월",Raw_Data!$AE:$AE,"기타수익",Raw_Data!$AF:$AF,"로열티수익") -> 447693 | D40: ← 선수협 퍼블리시티권 정산
A41: 로열티수익 | B41: Skybound | C41: =SUMIFS(Raw_Data!$G:$G,Raw_Data!$AG:$AG,"Skybound",Raw_Data!$AH:$AH,"4월",Raw_Data!$AE:$AE,"기타수익",Raw_Data!$AF:$AF,"로열티수익") -> 0
A42: 로열티수익 | B42: 공게임즈 | C42: =SUMIFS(Raw_Data!$G:$G,Raw_Data!$AG:$AG,"공게임즈",Raw_Data!$AH:$AH,"4월",Raw_Data!$AE:$AE,"기타수익",Raw_Data!$AF:$AF,"로열티수익") -> 22132224
...

Sheet Raw_Data
A1: No | B1: 계정코드 | C1: 계정명 | D1: 회계일 | E1: 승인번호 | F1: 차변 | G1: 대변 | H1: 잔액 | I1: 적요 | J1: 거래처코드 | K1: 거래처 | L1: 비용센터코드 | M1: 비용센터 | N1: 거래환종 | O1: 거래금액 | P1: 환율 | Q1: 프로젝트 | R1: 프로젝트명 | S1: 증빙 | T1: 예산단위 | U1: 예산계정 | V1: 회계단위 | W1: 작성부서 | X1: 작성자 | Y1: 전표번호 | Z1: 순번 | AA1: 메뉴 | AB1: 전표유형코드 | AC1: 전표유형명 | AD1: 계정유형 | AE1: 매출구분 | AF1: 세부구분 | AG1: 표시명 | AH1: 월 | AI1: 비고_매핑
A2: 1 | B2: 4100500 | C2: 기타수익 | D2: 46047 | E2: 3 | F2: 0 | G2: 33725108 | H2: 33725108 | I2: 2025년 4분기 그룹사 홍보비용 정산(홀딩스) | J2: C103422 | K2: 주식회사 컴투스홀딩스 | L2: 0100031561 | M2: (주)컴투스>경영전략부문>전략홍보실>커뮤니케이션1팀 | N2: KRW | O2: 33725108 | P2: 1 | Q2: Z0000 | R2: 공통 | S2: 세금계산서 | T2: 공통_수입결의서 | U2: 기타수익 | V2: (주)컴투스 | W2: (주)컴투스>경영전략부문>재무관리실>회계팀 | X2: 임회원 | Y2: FI20260125000003 | Z2: 1 | AA2: 결의서입력 | AB2: 11 | AC2: 일반 | AD2: K-IFRS(일반) | AE2: 기타수익 | AF2: 기타 | AG2: 컴투스홀딩스(기타) | AH2: 1월 | AI2: ← 그룹사 홍보비용 정산
A3: 2 | B3: 4100500 | C3: 기타수익 | D3: 46047 | E3: 3 | F3: 0 | G3: 14468693 | H3: 48193801 | I3: 2025년 4분기 그룹사 홍보비용 정산(플랫폼) | J3: C103421 | K3: 주식회사 컴투스플랫폼 | L3: 0100031561 | M3: (주)컴투스>경영전략부문>전략홍보실>커뮤니케이션1팀 | N3: KRW | O3: 14468693 | P3: 1 | Q3: Z0000 | R3: 공통 | S3: 세금계산서 | T3: 공통_수입결의서 | U3: 기타수익 | V3: (주)컴투스 | W3: (주)컴투스>경영전략부문>재무관리실>회계팀 | X3: 임회원 | Y3: FI20260125000003 | Z3: 4 | AA3: 결의서입력 | AB3: 11 | AC3: 일반 | AD3: K-IFRS(일반) | AE3: 기타수익 | AF3: 기타 | AG3: 컴투스플랫폼(기타) | AH3: 1월 | AI3: ← 컴투스 상표 로열티, 4사 공용비용 분담금
A4: 3 | B4: 4100500 | C4: 기타수익 | D4: 46052 | E4: 44 | F4: 0 | G4: 121442 | H4: 48315243 | I4: 01월/기타수익_매출/워너비챌린지 OST 음원매출 | J4: C100488 | K4: (주)에스비에스콘텐츠허브 | L4: CS10003290 | M4: (주)컴투스>사업운영센터>운영지원팀>운영지원2 | N4: KRW | O4: 121442 | P4: 1 | Q4: C0007 | R4: 워너비 | S4: 세금계산서 | T4: 공통_수입결의서 | U4: 기타수익 | V4: (주)컴투스 | W4: (주)컴투스>경영전략부문>재무관리실>회계팀 | X4: 유재원 | Y4: FI20260130000051 | Z4: 1 | AA4: 결의서입력 | AB4: 11 | AC4: 일반 | AD4: K-IFRS(일반) | AE4: 기타수익 | AF4: 기타 | AG4: 에스비에스콘텐츠허브 | AH4: 1월 | AI4: ← 워너비챌린지 음원매출
A5: 4 | B5: 4100500 | C5: 기타수익 | D5: 46053 | E5: 339 | F5: 0 | G5: 835680 | H5: 49150923 | I5: 26년 1월 카탈리스터 전대차 임대료 | J5: C103506 | K5: 주식회사 카탈리스터 | L5: 000000 | M5: 회사전체 | N5: KRW | O5: 835680 | P5: 1 | Q5: Z0000 | R5: 공통 | V5: (주)컴투스 | W5: (주)컴투스>경영전략부문>재무관리실>회계팀 | X5: 임회원 | Y5: FI20260131000348 | Z5: 2 | AA5: 전표입력 | AB5: 11 | AC5: 일반 | AD5: K-IFRS(일반) | AE5: 기타수익 | AF5: 기타 | AG5: 카탈리스터(기타) | AH5: 1월 | AI5: ← 4사 공용비용 분담금
A6: 5 | B6: 4100500 | C6: 기타수익 | D6: 46053 | E6: 338 | F6: 0 | G6: 175000 | H6: 49325923 | I6: 26년 1월 데이세븐 전대차 임대료 | J6: C102899 | K6: 주식회사 데이세븐 | L6: 000000 | M6: 회사전체 | N6: KRW | O6: 175000 | P6: 1 | Q6: Z0000 | R6: 공통 | V6: (주)컴투스 | W6: (주)컴투스>경영전략부문>재무관리실>회계팀 | X6: 임회원 | Y6: FI20260131000349 | Z6: 3 | AA6: 전표입력 | AB6: 11 | AC6: 일반 | AD6: K-IFRS(일반) | AE6: 기타수익 | AF6: 기타 | AG6: 데이세븐(기타) | AH6: 1월 | AI6: ← 전대차 임대료
A7: 6 | B7: 4100500 | C7: 기타수익 | D7: 46053 | E7: 341 | F7: 0 | G7: 13048244 | H7: 62374167 | I7: 1월분 4사 공용비용 분담 예상 금액_컴투스홀딩스 | J7: C103422 | K7: 주식회사 컴투스홀딩스 | L7: CS10003521 | M7: (주)컴투스>경영전략부문>재무관리실>회계팀 | N7: KRW | O7: 13048244 | P7: 1 | Q7: Z0000 | R7: 공통 | V7: (주)컴투스 | W7: (주)컴투스>경영전략부문>재무관리실>회계팀 | X7: 임회원 | Y7: FI20260131000357 | Z7: 2 | AA7: 전표입력 | AB7: 12 | AC7: 결산대체 | AD7: K-IFRS(일반) | AE7: 기타수익 | AF7: 기타 | AG7: 컴투스홀딩스(기타) | AH7: 1월 | AI7: ← 그룹사 홍보비용 정산
A8: 7 | B8: 4100500 | C8: 기타수익 | D8: 46053 | E8: 341 | F8: 0 | G8: 29397672 | H8: 91771839 | I8: 1월분 4사 공용비용 분담 예상 금액_컴투스플랫폼 | J8: C103421 | K8: 주식회사 컴투스플랫폼 | L8: CS10003521 | M8: (주)컴투스>경영전략부문>재무관리실>회계팀 | N8: KRW | O8: 29397672 | P8: 1 | Q8: Z0000 | R8: 공통 | V8: (주)컴투스 | W8: (주)컴투스>경영전략부문>재무관리실>회계팀 | X8: 임회원 | Y8: FI20260131000357 | Z8: 4 | AA8: 전표입력 | AB8: 12 | AC8: 결산대체 | AD8: K-IFRS(일반) | AE8: 기타수익 | AF8: 기타 | AG8: 컴투스플랫폼(기타) | AH8: 1월 | AI8: ← 컴투스 상표 로열티, 4사 공용비용 분담금
A9: 8 | B9: 4100500 | C9: 기타수익 | D9: 46053 | E9: 341 | F9: 0 | G9: 132223 | H9: 91904062 | I9: 1월분 4사 공용비용 분담 예상 금액_카탈리스터 | J9: C103506 | K9: 주식회사 카탈리스터 | L9: CS10003521 | M9: (주)컴투스>경영전략부문>재무관리실>회계팀 | N9: KRW | O9: 132223 | P9: 1 | Q9: Z0000 | R9: 공통 | V9: (주)컴투스 | W9: (주)컴투스>경영전략부문>재무관리실>회계팀 | X9: 임회원 | Y9: FI20260131000357 | Z9: 6 | AA9: 전표입력 | AB9: 12 | AC9: 결산대체 | AD9: K-IFRS(일반) | AE9: 기타수익 | AF9: 기타 | AG9: 카탈리스터(기타) | AH9: 1월 | AI9: ← 4사 공용비용 분담금
A10: 9 | B10: 4100500 | C10: 기타수익 | D10: 46053 | E10: 386 | F10: 0 | G10: 18413940 | H10: 110318002 | I10: 12월/매출_수익정산/하이브로 타이니팜＆드래곤럼블(2종게임) 매출 정산(2025년 12월) | J10: C104162 | K10: 주식회사 하이브로 | L10: CS10003276 | M10: (주)컴투스>사업운영센터>센트럴사업실 | N10: KRW | O10: 18413940 | P10: 1 | Q10: A0007 | R10: 타이니팜 | S10: 세금계산서 | T10: 공통_수입결의서 | U10: 기타수익 | V10: (주)컴투스 | W10: (주)컴투스>경영전략부문>재무관리실>회계팀 | X10: 유재원 | Y10: FI20260131000427 | Z10: 1 | AA10: 결의서입력 | AB10: 11 | AC10: 일반 | AD10: K-IFRS(일반) | AE10: 기타수익 | AF10: 기타 | AG10: 하이브로 | AH10: 1월 | AI10: ← 타이니팜/드래곤럼블 매출 정산
A11: 10 | B11: 4100500 | C11: 기타수익 | D11: 46053 | E11: 386 | F11: 0 | G11: 15551596 | H11: 125869598 | I11: 12월/매출_수익정산/하이브로 타이니팜＆드래곤럼블(2종게임) 매출 정산(2025년 12월) | J11: C104162 | K11: 주식회사 하이브로 | L11: CS10003276 | M11: (주)컴투스>사업운영센터>센트럴사업실 | N11: KRW | O11: 15551596 | P11: 1 | Q11: C0029 | R11: 전투기키우기 | S11: 세금계산서 | T11: 공통_수입결의서 | U11: 기타수익 | V11: (주)컴투스 | W11: (주)컴투스>경영전략부문>재무관리실>회계팀 | X11: 유재원 | Y11: FI20260131000427 | Z11: 4 | AA11: 결의서입력 | AB11: 11 | AC11: 일반 | AD11: K-IFRS(일반) | AE11: 기타수익 | AF11: 기타 | AG11: 하이브로 | AH11: 1월 | AI11: ← 타이니팜/드래곤럼블 매출 정산
A12: 11 | B12: 4100500 | C12: 기타수익 | D12: 46053 | E12: 387 | F12: 0 | G12: 831597 | H12: 126701195 | I12: 2026년 1월 붕어빵 타이쿤 IP로열티 정산분 | J12: C103421 | K12: 주식회사 컴투스플랫폼 | L12: CS10003409 | M12: (주)컴투스>게임사업담당>NR사업본부>글로벌사업실>글로벌전략팀 | N12: KRW | O12: 831597 | P12: 1 | Q12: Z0000 | R12: 공통 | S12: 세금계산서 | T12: 공통_수입결의서 | U12: 기타수익 | V12: (주)컴투스 | W12: (주)컴투스>경영전략부문>재무관리실>회계팀 | X12: 유재원 | Y12: FI20260131000428 | Z12: 1 | AA12: 결의서입력 | AB12: 11 | AC12: 일반 | AD12: K-IFRS(일반) | AE12: 기타수익 | AF12: 기타 | AG12: 컴투스플랫폼(기타) | AH12: 1월 | AI12: ← 컴투스 상표 로열티, 4사 공용비용 분담금
A13: 12 | B13: 4100500 | C13: 기타수익 | D13: 46053 | E13: 1094 | F13: 0 | G13: 2679557 | H13: 129380752 | I13: [매출/정산] 26년 1월 컴투스 상표 로열티_홀딩스 | J13: C103422 | K13: 주식회사 컴투스홀딩스 | L13: 000000 | M13: 회사전체 | N13: KRW | O13: 2679557 | P13: 1 | Q13: Z0000 | R13: 공통 | V13: (주)컴투스 | W13: (주)컴투스>경영전략부문>재무관리실>회계팀 | X13: 유재원 | Y13: FI20260131000438 | Z13: 1 | AA13: 전표입력 | AB13: 11 | AC13: 일반 | AD13: K-IFRS(일반) | AE13: 기타수익 | AF13: 기타 | AG13: 컴투스홀딩스(기타) | AH13: 1월 | AI13: ← 그룹사 홍보비용 정산
A14: 13 | B14: 4100500 | C14: 기타수익 | D14: 46053 | E14: 1094 | F14: 0 | G14: 612796 | H14: 129993548 | I14: [매출/정산] 26년 1월 컴투스 상표 로열티_플랫폼 | J14: C103421 | K14: 주식회사 컴투스플랫폼 | L14: 000000 | M14: 회사전체 | N14: KRW | O14: 612796 | P14: 1 | Q14: Z0000 | R14: 공통 | V14: (주)컴투스 | W14: (주)컴투스>경영전략부문>재무관리실>회계팀 | X14: 유재원 | Y14: FI20260131000438 | Z14: 4 | AA14: 전표입력 | AB14: 11 | AC14: 일반 | AD14: K-IFRS(일반) | AE14: 기타수익 | AF14: 기타 | AG14: 컴투스플랫폼(기타) | AH14: 1월 | AI14: ← 컴투스 상표 로열티, 4사 공용비용 분담금
A15: 14 | B15: 4100500 | C15: 기타수익 | D15: 46053 | E15: 1143 | F15: 0 | G15: 600000 | H15: 130593548 | I15: 1월/복리후생비/26년 1월 임원 복리후생 이용 정산 건 | J15: C103421 | K15: 주식회사 컴투스플랫폼 | L15: CS10003374 | M15: (주)컴투스>경영전략부문>인사실>인사운영팀 | N15: KRW | O15: 600000 | P15: 1 | Q15: Z0000 | R15: 공통 | S15: 세금계산서 | T15: 공통_수입결의서 | U15: 기타수익 | V15: (주)컴투스 | W15: (주)컴투스>경영전략부문>재무관리실>회계팀 | X15: 김보훈 | Y15: FI20260131001166 | Z15: 1 | AA15: 결의서입력 | AB15: 11 | AC15: 일반 | AD15: K-IFRS(일반) | AE15: 기타수익 | AF15: 기타 | AG15: 컴투스플랫폼(기타) | AH15: 1월 | AI15: ← 컴투스 상표 로열티, 4사 공용비용 분담금
A16: 16 | B16: 4100500 | C16: 기타수익 | D16: 46053 | E16: 1187 | F16: 0 | G16: 989829 | H16: 447697 | I16: 1월 선수협 퍼블리시티권 정산_공게임즈_이사만루 예정-확정 차이 (25.12 매출) | J16: C103591 | K16: (주) 공게임즈 | L16: CS10003276 | M16: (주)컴투스>사업운영센터>센트럴사업실 | N16: KRW | O16: 989829 | P16: 1 | Q16: Z0000 | R16: 공통 | V16: (주)컴투스 | W16: (주)컴투스>경영전략부문>재무관리실>회계팀 | X16: 유재원 | Y16: FI20260227000008 | Z16: 10 | AA16: 전표입력 | AB16: 11 | AC16: 일반 | AD16: K-IFRS(일반) | AE16: 기타수익 | AF16: 로열티수익 | AG16: 공게임즈 | AH16: 1월
A17: 17 | B17: 4100500 | C17: 기타수익 | D17: 46053 | E17: 1187 | F17: 0 | G17: -367497 | H17: 80200 | I17: 1월 선수협 퍼블리시티권 정산_넷마블_마구마구 예정-확정 차이 (25.12 매출) | J17: C102096 | K17: 넷마블 주식회사 | L17: CS10003276 | M17: (주)컴투스>사업운영센터>센트럴사업실 | N17: KRW | O17: -367497 | P17: 1 | Q17: Z0000 | R17: 공통 | V17: (주)컴투스 | W17: (주)컴투스>경영전략부문>재무관리실>회계팀 | X17: 유재원 | Y17: FI20260227000008 | Z17: 11 | AA17: 전표입력 | AB17: 11 | AC17: 일반 | AD17: K-IFRS(일반) | AE17: 기타수익 | AF17: 기타 | AG17: 넷마블(기타) | AH17: 1월
A18: 18 | B18: 4100500 | C18: 기타수익 | D18: 46053 | E18: 1187 | F18: 0 | G18: -80200 | H18: 0 | I18: 1월 선수협 퍼블리시티권 정산_에이스프로젝트_9UP프로야구 예정-확정 차이 (25.12 매출) | J18: C101857 | K18: 주식회사 에이스프로젝트 | L18: CS10003276 | M18: (주)컴투스>사업운영센터>센트럴사업실 | N18: KRW | O18: -80200 | P18: 1 | Q18: Z0000 | R18: 공통 | V18: (주)컴투스 | W18: (주)컴투스>경영전략부문>재무관리실>회계팀 | X18: 유재원 | Y18: FI20260227000008 | Z18: 12 | AA18: 전표입력 | AB18: 11 | AC18: 일반 | AD18: K-IFRS(일반) | AE18: 기타수익 | AF18: 로열티수익 | AG18: 에이스프로젝트 | AH18: 1월
A19: 21 | B19: 4100500 | C19: 기타수익 | D19: 46054 | E19: 22 | F19: 0 | G19: 31189 | H19: 31189 | I19: 2월/로열티 매출/ 25년 4Q KENAZ의 '서머너즈 워' IP 웹툰 6종 서비스 원작료 정산 | J19: C103236 | K19: 주식회사 케나즈 | L19: CS10003409 | M19: (주)컴투스>게임사업담당>NR사업본부>글로벌사업실>글로벌전략팀 | N19: KRW | O19: 31189 | P19: 1 | Q19: A0001 | R19: 서머너즈워 | S19: 세금계산서 | T19: 공통_수입결의서 | U19: 기타수익 | V19: (주)컴투스 | W19: (주)컴투스>경영전략부문>재무관리실>내부회계관리팀 | X19: 유재원 | Y19: FI20260201000027 | Z19: 1 | AA19: 결의서입력 | AB19: 11 | AC19: 일반 | AD19: K-IFRS(일반) | AE19: 기타수익 | AF19: 로열티수익 | AG19: 케나즈 | AH19: 2월 | AI19: ← 서머너즈워 IP 활용 웹툰 정산금
A20: 22 | B20: 4100500 | C20: 기타수익 | D20: 46080 | E20: 45 | F20: 0 | G20: 117215 | H20: 148404 | I20: 02월/기타수익_매출/워너비챌린지 OST 음원매출 | J20: C100488 | K20: (주)에스비에스콘텐츠허브 | L20: CS10003577 | M20: (주)컴투스>게임사업담당>NR사업본부>게임운영실>게임운영지원TF | N20: KRW | O20: 117215 | P20: 1 | Q20: C0007 | R20: 워너비 | S20: 세금계산서 | T20: 공통_수입결의서 | U20: 기타수익 | V20: (주)컴투스 | W20: (주)컴투스>경영전략부문>재무관리실>내부회계관리팀 | X20: 유재원 | Y20: FI20260227000054 | Z20: 1 | AA20: 결의서입력 | AB20: 11 | AC20: 일반 | AD20: K-IFRS(일반) | AE20: 기타수익 | AF20: 기타 | AG20: 에스비에스콘텐츠허브 | AH20: 2월 | AI20: ← 워너비챌린지 음원매출
A21: 23 | B21: 4100500 | C21: 기타수익 | D21: 46081 | E21: 186 | F21: 0 | G21: 835680 | H21: 984084 | I21: [기타매출] 2월 카탈리스터 전대차 임대료 | J21: C103506 | K21: 주식회사 카탈리스터 | L21: 000000 | M21: 회사전체 | N21: KRW | O21: 835680 | P21: 1 | Q21: Z0000 | R21: 공통 | V21: (주)컴투스 | W21: (주)컴투스>경영전략부문>재무관리실>회계팀 | X21: 임회원 | Y21: FI20260228000154 | Z21: 2 | AA21: 전표입력 | AB21: 11 | AC21: 일반 | AD21: K-IFRS(일반) | AE21: 기타수익 | AF21: 기타 | AG21: 카탈리스터(기타) | AH21: 2월 | AI21: ← 4사 공용비용 분담금
A22: 24 | B22: 4100500 | C22: 기타수익 | D22: 46081 | E22: 186 | F22: 0 | G22: 175000 | H22: 1159084 | I22: [기타매출] 2월 데이세븐 전대차 임대료 | J22: C102899 | K22: 주식회사 데이세븐 | L22: 000000 | M22: 회사전체 | N22: KRW | O22: 175000 | P22: 1 | Q22: Z0000 | R22: 공통 | V22: (주)컴투스 | W22: (주)컴투스>경영전략부문>재무관리실>회계팀 | X22: 임회원 | Y22: FI20260228000154 | Z22: 5 | AA22: 전표입력 | AB22: 11 | AC22: 일반 | AD22: K-IFRS(일반) | AE22: 기타수익 | AF22: 기타 | AG22: 데이세븐(기타) | AH22: 2월 | AI22: ← 전대차 임대료
A23: 25 | B23: 4100500 | C23: 기타수익 | D23: 46081 | E23: 1014 | F23: 0 | G23: 2798183 | H23: 3957267 | I23: [매출/정산] 26년 2월 컴투스 상표 로열티_홀딩스 | J23: C103422 | K23: 주식회사 컴투스홀딩스 | L23: 000000 | M23: 회사전체 | N23: KRW | O23: 2798183 | P23: 1 | Q23: Z0000 | R23: 공통 | V23: (주)컴투스 | W23: (주)컴투스>경영전략부문>재무관리실>내부회계관리팀 | X23: 유재원 | Y23: FI20260228000215 | Z23: 1 | AA23: 전표입력 | AB23: 11 | AC23: 일반 | AD23: K-IFRS(일반) | AE23: 기타수익 | AF23: 기타 | AG23: 컴투스홀딩스(기타) | AH23: 2월 | AI23: ← 그룹사 홍보비용 정산
A24: 26 | B24: 4100500 | C24: 기타수익 | D24: 46081 | E24: 1014 | F24: 0 | G24: 549265 | H24: 4506532 | I24: [매출/정산] 26년 2월 컴투스 상표 로열티_플랫폼 | J24: C103421 | K24: 주식회사 컴투스플랫폼 | L24: 000000 | M24: 회사전체 | N24: KRW | O24: 549265 | P24: 1 | Q24: Z0000 | R24: 공통 | V24: (주)컴투스 | W24: (주)컴투스>경영전략부문>재무관리실>내부회계관리팀 | X24: 유재원 | Y24: FI20260228000215 | Z24: 4 | AA24: 전표입력 | AB24: 11 | AC24: 일반 | AD24: K-IFRS(일반) | AE24: 기타수익 | AF24: 기타 | AG24: 컴투스플랫폼(기타) | AH24: 2월 | AI24: ← 컴투스 상표 로열티, 4사 공용비용 분담금
A25: 27 | B25: 4100500 | C25: 기타수익 | D25: 46081 | E25: 202 | F25: 0 | G25: 314225 | H25: 4820757 | I25: 2026년 2월 붕어빵 타이쿤 IP로열티 정산분 | J25: C103421 | K25: 주식회사 컴투스플랫폼 | L25: CS10003409 | M25: (주)컴투스>게임사업담당>NR사업본부>글로벌사업실>글로벌전략팀 | N25: KRW | O25: 314225 | P25: 1 | Q25: Z0000 | R25: 공통 | S25: 세금계산서 | T25: 공통_수입결의서 | U25: 기타수익 | V25: (주)컴투스 | W25: (주)컴투스>경영전략부문>재무관리실>내부회계관리팀 | X25: 유재원 | Y25: FI20260228000226 | Z25: 1 | AA25: 결의서입력 | AB25: 11 | AC25: 일반 | AD25: K-IFRS(일반) | AE25: 기타수익 | AF25: 기타 | AG25: 컴투스플랫폼(기타) | AH25: 2월 | AI25: ← 컴투스 상표 로열티, 4사 공용비용 분담금
A26: 28 | B26: 4100500 | C26: 기타수익 | D26: 46081 | E26: 203 | F26: 0 | G26: 17227545 | H26: 22048302 | I26: 01월/매출_수익정산/하이브로 타이니팜 매출 정산(2026년 01월) | J26: C104162 | K26: 주식회사 하이브로 | L26: CS10003276 | M26: (주)컴투스>사업운영센터>센트럴사업실 | N26: KRW | O26: 17227545 | P26: 1 | Q26: A0007 | R26: 타이니팜 | S26: 세금계산서 | T26: 공통_수입결의서 | U26: 기타수익 | V26: (주)컴투스 | W26: (주)컴투스>경영전략부문>재무관리실>내부회계관리팀 | X26: 유재원 | Y26: FI20260228000227 | Z26: 1 | AA26: 결의서입력 | AB26: 11 | AC26: 일반 | AD26: K-IFRS(일반) | AE26: 기타수익 | AF26: 기타 | AG26: 하이브로 | AH26: 2월 | AI26: ← 타이니팜/드래곤럼블 매출 정산
A27: 29 | B27: 4100500 | C27: 기타수익 | D27: 46081 | E27: 203 | F27: 0 | G27: 4734168 | H27: 26782470 | I27: 01월/매출_수익정산/하이브로 드래곤럼블 매출 정산(2026년 01월) | J27: C104162 | K27: 주식회사 하이브로 | L27: CS10003276 | M27: (주)컴투스>사업운영센터>센트럴사업실 | N27: KRW | O27: 4734168 | P27: 1 | Q27: C0029 | R27: 전투기키우기 | S27: 세금계산서 | T27: 공통_수입결의서 | U27: 기타수익 | V27: (주)컴투스 | W27: (주)컴투스>경영전략부문>재무관리실>내부회계관리팀 | X27: 유재원 | Y27: FI20260228000227 | Z27: 4 | AA27: 결의서입력 | AB27: 11 | AC27: 일반 | AD27: K-IFRS(일반) | AE27: 기타수익 | AF27: 기타 | AG27: 하이브로 | AH27: 2월 | AI27: ← 타이니팜/드래곤럼블 매출 정산
A28: 30 | B28: 4100500 | C28: 기타수익 | D28: 46081 | E28: 1041 | F28: 0 | G28: 11241702 | H28: 38024172 | I28: [매출 / 가인식] 1월 그룹사 홍보비용 정산(홀딩스) | J28: C103422 | K28: 주식회사 컴투스홀딩스 | L28: CS10003521 | M28: (주)컴투스>경영전략부문>재무관리실>회계팀 | N28: KRW | O28: 11241702 | P28: 1 | Q28: Z0000 | R28: 공통 | V28: (주)컴투스 | W28: (주)컴투스>경영전략부문>재무관리실>회계팀 | X28: 임회원 | Y28: FI20260228001061 | Z28: 1 | AA28: 전표입력 | AB28: 12 | AC28: 결산대체 | AD28: K-IFRS(일반) | AE28: 기타수익 | AF28: 기타 | AG28: 컴투스홀딩스(기타) | AH28: 2월 | AI28: ← 그룹사 홍보비용 정산
A29: 31 | B29: 4100500 | C29: 기타수익 | D29: 46081 | E29: 1041 | F29: 0 | G29: 11241702 | H29: 49265874 | I29: [매출 / 가인식] 2월 그룹사 홍보비용 정산(홀딩스) | J29: C103422 | K29: 주식회사 컴투스홀딩스 | L29: CS10003521 | M29: (주)컴투스>경영전략부문>재무관리실>회계팀 | N29: KRW | O29: 11241702 | P29: 1 | Q29: Z0000 | R29: 공통 | V29: (주)컴투스 | W29: (주)컴투스>경영전략부문>재무관리실>회계팀 | X29: 임회원 | Y29: FI20260228001061 | Z29: 3 | AA29: 전표입력 | AB29: 12 | AC29: 결산대체 | AD29: K-IFRS(일반) | AE29: 기타수익 | AF29: 기타 | AG29: 컴투스홀딩스(기타) | AH29: 2월 | AI29: ← 그룹사 홍보비용 정산
A30: 32 | B30: 4100500 | C30: 기타수익 | D30: 46081 | E30: 1041 | F30: 0 | G30: 4822897 | H30: 54088771 | I30: [매출 / 가인식] 1월 그룹사 홍보비용 정산(플랫폼) | J30: C103421 | K30: 주식회사 컴투스플랫폼 | L30: CS10003521 | M30: (주)컴투스>경영전략부문>재무관리실>회계팀 | N30: KRW | O30: 4822897 | P30: 1 | Q30: Z0000 | R30: 공통 | V30: (주)컴투스 | W30: (주)컴투스>경영전략부문>재무관리실>회계팀 | X30: 임회원 | Y30: FI20260228001061 | Z30: 5 | AA30: 전표입력 | AB30: 12 | AC30: 결산대체 | AD30: K-IFRS(일반) | AE30: 기타수익 | AF30: 기타 | AG30: 컴투스플랫폼(기타) | AH30: 2월 | AI30: ← 컴투스 상표 로열티, 4사 공용비용 분담금
A31: 33 | B31: 4100500 | C31: 기타수익 | D31: 46081 | E31: 1041 | F31: 0 | G31: 4822897 | H31: 58911668 | I31: [매출 / 가인식] 2월 그룹사 홍보비용 정산(플랫폼) | J31: C103421 | K31: 주식회사 컴투스플랫폼 | L31: CS10003521 | M31: (주)컴투스>경영전략부문>재무관리실>회계팀 | N31: KRW | O31: 4822897 | P31: 1 | Q31: Z0000 | R31: 공통 | V31: (주)컴투스 | W31: (주)컴투스>경영전략부문>재무관리실>회계팀 | X31: 임회원 | Y31: FI20260228001061 | Z31: 7 | AA31: 전표입력 | AB31: 12 | AC31: 결산대체 | AD31: K-IFRS(일반) | AE31: 기타수익 | AF31: 기타 | AG31: 컴투스플랫폼(기타) | AH31: 2월 | AI31: ← 컴투스 상표 로열티, 4사 공용비용 분담금
A32: 34 | B32: 4100500 | C32: 기타수익 | D32: 46081 | E32: 1174 | F32: 0 | G32: 9618919 | H32: 68530587 | I32: 2월 / 수입결의서 / 운영시스템 양도 1차/20260226/23/FI20260226000025-1 | J32: C103732 | K32: (주)게임테일즈 | L32: CS10003467 | M32: (주)컴투스>게임사업담당>NR사업본부>IG사업실>LT사업부 | N32: KRW | O32: 9618919 | P32: 1 | Q32: D0010 | R32: 더스타라이트 | V32: (주)컴투스 | W32: (주)컴투스>경영전략부문>재무관리실>회계팀 | X32: 김보훈 | Y32: FI20260228001185 | Z32: 2 | AA32: 전표입력 | AB32: 11 | AC32: 일반 | AD32: K-IFRS(일반) | AE32: 기타수익 | AF32: 기타 | AG32: 게임테일즈 | AH32: 2월 | AI32: ← 게임테일즈 운영시스템 양도/IP 사용료
A33: 36 | B33: 4100500 | C33: 기타수익 | D33: 46081 | E33: 185 | F33: 0 | G33: 13048244 | H33: -29529895 | I33: [기타매출 / 가인식] 2월 4사 공용비용 분담금_컴투스홀딩스 | J33: C103422 | K33: 주식회사 컴투스홀딩스 | L33: CS10003521 | M33: (주)컴투스>경영전략부문>재무관리실>회계팀 | N33: KRW | O33: 13048244 | P33: 1 | Q33: Z0000 | R33: 공통 | V33: (주)컴투스 | W33: (주)컴투스>경영전략부문>재무관리실>회계팀 | X33: 임회원 | Y33: FI20260309000001 | Z33: 2 | AA33: 전표입력 | AB33: 12 | AC33: 결산대체 | AD33: K-IFRS(일반) | AE33: 기타수익 | AF33: 기타 | AG33: 컴투스홀딩스(기타) | AH33: 2월 | AI33: ← 그룹사 홍보비용 정산
A34: 37 | B34: 4100500 | C34: 기타수익 | D34: 46081 | E34: 185 | F34: 0 | G34: 29397672 | H34: -132223 | I34: [기타매출 / 가인식] 2월 4사 공용비용 분담금_컴투스플랫폼 | J34: C103421 | K34: 주식회사 컴투스플랫폼 | L34: CS10003521 | M34: (주)컴투스>경영전략부문>재무관리실>회계팀 | N34: KRW | O34: 29397672 | P34: 1 | Q34: Z0000 | R34: 공통 | V34: (주)컴투스 | W34: (주)컴투스>경영전략부문>재무관리실>회계팀 | X34: 임회원 | Y34: FI20260309000001 | Z34: 4 | AA34: 전표입력 | AB34: 12 | AC34: 결산대체 | AD34: K-IFRS(일반) | AE34: 기타수익 | AF34: 기타 | AG34: 컴투스플랫폼(기타) | AH34: 2월 | AI34: ← 컴투스 상표 로열티, 4사 공용비용 분담금
A35: 38 | B35: 4100500 | C35: 기타수익 | D35: 46081 | E35: 185 | F35: 0 | G35: 132223 | H35: 0 | I35: [기타매출 / 가인식] 2월 4사 공용비용 분담금_카탈리스터 | J35: C103506 | K35: 주식회사 카탈리스터 | L35: CS10003521 | M35: (주)컴투스>경영전략부문>재무관리실>회계팀 | N35: KRW | O35: 132223 | P35: 1 | Q35: Z0000 | R35: 공통 | V35: (주)컴투스 | W35: (주)컴투스>경영전략부문>재무관리실>회계팀 | X35: 임회원 | Y35: FI20260309000001 | Z35: 6 | AA35: 전표입력 | AB35: 12 | AC35: 결산대체 | AD35: K-IFRS(일반) | AE35: 기타수익 | AF35: 기타 | AG35: 카탈리스터(기타) | AH35: 2월 | AI35: ← 4사 공용비용 분담금
A36: 41 | B36: 4100500 | C36: 기타수익 | D36: 46082 | E36: 38 | F36: 0 | G36: -5351351 | H36: -5351351 | I36: 2월 게임 테일즈 운영시스템 양도 1차 (20%) /원전표 FI20260228001185 | J36: C103732 | K36: (주)게임테일즈 | L36: CS10003467 | M36: (주)컴투스>게임사업담당>NR사업본부>IG사업실>LT사업부 | N36: KRW | O36: -5351351 | P36: 1 | Q36: D0010 | R36: 더스타라이트 | V36: (주)컴투스 | W36: (주)컴투스>경영전략부문>재무관리실>내부회계관리팀 | X36: 유재원 | Y36: FI20260301000033 | Z36: 4 | AA36: 전표입력 | AB36: 11 | AC36: 일반 | AD36: K-IFRS(일반) | AE36: 기타수익 | AF36: 기타 | AG36: 게임테일즈 | AH36: 3월 | AI36: ← 게임테일즈 운영시스템 양도/IP 사용료
A37: 42 | B37: 4100500 | C37: 기타수익 | D37: 46112 | E37: 205 | F37: 0 | G37: 835680 | H37: -4515671 | I37: [기타매출] 3월 카탈리스터 전대차 임대료 | J37: C103506 | K37: 주식회사 카탈리스터 | L37: 000000 | M37: 회사전체 | N37: KRW | O37: 835680 | P37: 1 | Q37: Z0000 | R37: 공통 | V37: (주)컴투스 | W37: (주)컴투스>경영전략부문>재무관리실>회계세무팀 | X37: 임회원 | Y37: FI20260331000230 | Z37: 2 | AA37: 전표입력 | AB37: 11 | AC37: 일반 | AD37: K-IFRS(일반) | AE37: 기타수익 | AF37: 기타 | AG37: 카탈리스터(기타) | AH37: 3월 | AI37: ← 4사 공용비용 분담금
A38: 43 | B38: 4100500 | C38: 기타수익 | D38: 46112 | E38: 205 | F38: 0 | G38: 175000 | H38: -4340671 | I38: [기타매출] 3월 데이세븐 전대차 임대료 | J38: C102899 | K38: 주식회사 데이세븐 | L38: 000000 | M38: 회사전체 | N38: KRW | O38: 175000 | P38: 1 | Q38: Z0000 | R38: 공통 | V38: (주)컴투스 | W38: (주)컴투스>경영전략부문>재무관리실>회계세무팀 | X38: 임회원 | Y38: FI20260331000230 | Z38: 5 | AA38: 전표입력 | AB38: 11 | AC38: 일반 | AD38: K-IFRS(일반) | AE38: 기타수익 | AF38: 기타 | AG38: 데이세븐(기타) | AH38: 3월 | AI38: ← 전대차 임대료
A39: 44 | B39: 4100500 | C39: 기타수익 | D39: 46112 | E39: 209 | F39: 0 | G39: 6986725 | H39: 2646054 | I39: [기타매출 / 확정] 3월 4사 공용비용 분담금_컴투스홀딩스 | J39: C103422 | K39: 주식회사 컴투스홀딩스 | L39: CS10003521 | M39: (주)컴투스>경영전략부문>재무관리실>회계팀 | N39: KRW | O39: 6986725 | P39: 1 | Q39: Z0000 | R39: 공통 | S39: 세금계산서 | T39: 공통_수입결의서 | U39: 기타수익 | V39: (주)컴투스 | W39: (주)컴투스>경영전략부문>재무관리실>회계세무팀 | X39: 임회원 | Y39: FI20260331000231 | Z39: 1 | AA39: 전표입력 | AB39: 11 | AC39: 일반 | AD39: K-IFRS(일반) | AE39: 기타수익 | AF39: 기타 | AG39: 컴투스홀딩스(기타) | AH39: 3월 | AI39: ← 그룹사 홍보비용 정산
A40: 45 | B40: 4100500 | C40: 기타수익 | D40: 46112 | E40: 209 | F40: 0 | G40: 27819175 | H40: 30465229 | I40: [기타매출 / 확정] 3월 4사 공용비용 분담금_컴투스플랫폼 | J40: C103421 | K40: 주식회사 컴투스플랫폼 | L40: CS10003521 | M40: (주)컴투스>경영전략부문>재무관리실>회계팀 | N40: KRW | O40: 27819175 | P40: 1 | Q40: Z0000 | R40: 공통 | S40: 세금계산서 | T40: 공통_수입결의서 | U40: 기타수익 | V40: (주)컴투스 | W40: (주)컴투스>경영전략부문>재무관리실>회계세무팀 | X40: 임회원 | Y40: FI20260331000231 | Z40: 4 | AA40: 전표입력 | AB40: 11 | AC40: 일반 | AD40: K-IFRS(일반) | AE40: 기타수익 | AF40: 기타 | AG40: 컴투스플랫폼(기타) | AH40: 3월 | AI40: ← 컴투스 상표 로열티, 4사 공용비용 분담금
...

Sheet 검색
A1: Raw_Data 상세 조회
A2: 월 | B2: (전체) | C2: 드롭다운 또는 쉼표(,)로 다중입력 (예: 5월,6월) | (전체) 선택시 해당 조건 미적용
A3: 거래처(표시명) | B3: (전체)
A4: 매출구분 | B4: (전체)
A6: No | B6: 거래처 | C6: 회계일 | D6: 월 | E6: 대변 | F6: 매출구분 | G6: 세부구분 | H6: 표시명 | I6: 적요 | J6: 비고_매핑
A7: {=_xlfn._xlws.FILTER(CHOOSE({1,2,3,4,5,6,7,8,9,10},Raw_Data!$A$2:$A$777,Raw_Data!$K$2:$K$777,Raw_Data!$D$2:$D$777,Raw_Data!$AH$2:$AH$777,Raw_Data!$G$2:$G$777,Raw_Data!$AE$2:$AE$777,Raw_Data!$AF$2:$AF$777,Raw_Data!$AG$2:$AG$777,Raw_Data!$I$2:$I$777,Raw_Data!$AI$2:$AI$777),(($B$2="(전체)")+ISNUMBER(SEARCH(","&Raw_Data!$AH$2:$AH$777&",",","&SUBSTITUTE($B$2," ","")&",")))*(($B$3="(전체)")+ISNUMBER(SEARCH(","&Raw_Data!$AG$2:$AG$777&",",","&SUBSTITUTE($B$3," ","")&",")))*(($B$4="(전체)")+(Raw_Data!$AE$2:$AE$777=$B$4)),"")} -> 1 | B7: 주식회사 컴투스홀딩스 | C7: 46047 | D7: 1월 | E7: 33725108 | F7: 기타수익 | G7: 기타 | H7: 컴투스홀딩스(기타) | I7: 2025년 4분기 그룹사 홍보비용 정산(홀딩스) | J7: ← 그룹사 홍보비용 정산
A8: 2 | B8: 주식회사 컴투스플랫폼 | C8: 46047 | D8: 1월 | E8: 14468693 | F8: 기타수익 | G8: 기타 | H8: 컴투스플랫폼(기타) | I8: 2025년 4분기 그룹사 홍보비용 정산(플랫폼) | J8: ← 컴투스 상표 로열티, 4사 공용비용 분담금
A9: 3 | B9: (주)에스비에스콘텐츠허브 | C9: 46052 | D9: 1월 | E9: 121442 | F9: 기타수익 | G9: 기타 | H9: 에스비에스콘텐츠허브 | I9: 01월/기타수익_매출/워너비챌린지 OST 음원매출 | J9: ← 워너비챌린지 음원매출
A10: 4 | B10: 주식회사 카탈리스터 | C10: 46053 | D10: 1월 | E10: 835680 | F10: 기타수익 | G10: 기타 | H10: 카탈리스터(기타) | I10: 26년 1월 카탈리스터 전대차 임대료 | J10: ← 4사 공용비용 분담금
A11: 5 | B11: 주식회사 데이세븐 | C11: 46053 | D11: 1월 | E11: 175000 | F11: 기타수익 | G11: 기타 | H11: 데이세븐(기타) | I11: 26년 1월 데이세븐 전대차 임대료 | J11: ← 전대차 임대료
A12: 6 | B12: 주식회사 컴투스홀딩스 | C12: 46053 | D12: 1월 | E12: 13048244 | F12: 기타수익 | G12: 기타 | H12: 컴투스홀딩스(기타) | I12: 1월분 4사 공용비용 분담 예상 금액_컴투스홀딩스 | J12: ← 그룹사 홍보비용 정산
A13: 7 | B13: 주식회사 컴투스플랫폼 | C13: 46053 | D13: 1월 | E13: 29397672 | F13: 기타수익 | G13: 기타 | H13: 컴투스플랫폼(기타) | I13: 1월분 4사 공용비용 분담 예상 금액_컴투스플랫폼 | J13: ← 컴투스 상표 로열티, 4사 공용비용 분담금
A14: 8 | B14: 주식회사 카탈리스터 | C14: 46053 | D14: 1월 | E14: 132223 | F14: 기타수익 | G14: 기타 | H14: 카탈리스터(기타) | I14: 1월분 4사 공용비용 분담 예상 금액_카탈리스터 | J14: ← 4사 공용비용 분담금
A15: 9 | B15: 주식회사 하이브로 | C15: 46053 | D15: 1월 | E15: 18413940 | F15: 기타수익 | G15: 기타 | H15: 하이브로 | I15: 12월/매출_수익정산/하이브로 타이니팜＆드래곤럼블(2종게임) 매출 정산(2025년 12월) | J15: ← 타이니팜/드래곤럼블 매출 정산
A16: 10 | B16: 주식회사 하이브로 | C16: 46053 | D16: 1월 | E16: 15551596 | F16: 기타수익 | G16: 기타 | H16: 하이브로 | I16: 12월/매출_수익정산/하이브로 타이니팜＆드래곤럼블(2종게임) 매출 정산(2025년 12월) | J16: ← 타이니팜/드래곤럼블 매출 정산
A17: 11 | B17: 주식회사 컴투스플랫폼 | C17: 46053 | D17: 1월 | E17: 831597 | F17: 기타수익 | G17: 기타 | H17: 컴투스플랫폼(기타) | I17: 2026년 1월 붕어빵 타이쿤 IP로열티 정산분 | J17: ← 컴투스 상표 로열티, 4사 공용비용 분담금
A18: 12 | B18: 주식회사 컴투스홀딩스 | C18: 46053 | D18: 1월 | E18: 2679557 | F18: 기타수익 | G18: 기타 | H18: 컴투스홀딩스(기타) | I18: [매출/정산] 26년 1월 컴투스 상표 로열티_홀딩스 | J18: ← 그룹사 홍보비용 정산
A19: 13 | B19: 주식회사 컴투스플랫폼 | C19: 46053 | D19: 1월 | E19: 612796 | F19: 기타수익 | G19: 기타 | H19: 컴투스플랫폼(기타) | I19: [매출/정산] 26년 1월 컴투스 상표 로열티_플랫폼 | J19: ← 컴투스 상표 로열티, 4사 공용비용 분담금
A20: 14 | B20: 주식회사 컴투스플랫폼 | C20: 46053 | D20: 1월 | E20: 600000 | F20: 기타수익 | G20: 기타 | H20: 컴투스플랫폼(기타) | I20: 1월/복리후생비/26년 1월 임원 복리후생 이용 정산 건 | J20: ← 컴투스 상표 로열티, 4사 공용비용 분담금
A21: 16 | B21: (주) 공게임즈 | C21: 46053 | D21: 1월 | E21: 989829 | F21: 기타수익 | G21: 로열티수익 | H21: 공게임즈 | I21: 1월 선수협 퍼블리시티권 정산_공게임즈_이사만루 예정-확정 차이 (25.12 매출) | J21: 0
A22: 17 | B22: 넷마블 주식회사 | C22: 46053 | D22: 1월 | E22: -367497 | F22: 기타수익 | G22: 기타 | H22: 넷마블(기타) | I22: 1월 선수협 퍼블리시티권 정산_넷마블_마구마구 예정-확정 차이 (25.12 매출) | J22: 0
A23: 18 | B23: 주식회사 에이스프로젝트 | C23: 46053 | D23: 1월 | E23: -80200 | F23: 기타수익 | G23: 로열티수익 | H23: 에이스프로젝트 | I23: 1월 선수협 퍼블리시티권 정산_에이스프로젝트_9UP프로야구 예정-확정 차이 (25.12 매출) | J23: 0
A24: 21 | B24: 주식회사 케나즈 | C24: 46054 | D24: 2월 | E24: 31189 | F24: 기타수익 | G24: 로열티수익 | H24: 케나즈 | I24: 2월/로열티 매출/ 25년 4Q KENAZ의 '서머너즈 워' IP 웹툰 6종 서비스 원작료 정산 | J24: ← 서머너즈워 IP 활용 웹툰 정산금
A25: 22 | B25: (주)에스비에스콘텐츠허브 | C25: 46080 | D25: 2월 | E25: 117215 | F25: 기타수익 | G25: 기타 | H25: 에스비에스콘텐츠허브 | I25: 02월/기타수익_매출/워너비챌린지 OST 음원매출 | J25: ← 워너비챌린지 음원매출
A26: 23 | B26: 주식회사 카탈리스터 | C26: 46081 | D26: 2월 | E26: 835680 | F26: 기타수익 | G26: 기타 | H26: 카탈리스터(기타) | I26: [기타매출] 2월 카탈리스터 전대차 임대료 | J26: ← 4사 공용비용 분담금
A27: 24 | B27: 주식회사 데이세븐 | C27: 46081 | D27: 2월 | E27: 175000 | F27: 기타수익 | G27: 기타 | H27: 데이세븐(기타) | I27: [기타매출] 2월 데이세븐 전대차 임대료 | J27: ← 전대차 임대료
A28: 25 | B28: 주식회사 컴투스홀딩스 | C28: 46081 | D28: 2월 | E28: 2798183 | F28: 기타수익 | G28: 기타 | H28: 컴투스홀딩스(기타) | I28: [매출/정산] 26년 2월 컴투스 상표 로열티_홀딩스 | J28: ← 그룹사 홍보비용 정산
A29: 26 | B29: 주식회사 컴투스플랫폼 | C29: 46081 | D29: 2월 | E29: 549265 | F29: 기타수익 | G29: 기타 | H29: 컴투스플랫폼(기타) | I29: [매출/정산] 26년 2월 컴투스 상표 로열티_플랫폼 | J29: ← 컴투스 상표 로열티, 4사 공용비용 분담금
A30: 27 | B30: 주식회사 컴투스플랫폼 | C30: 46081 | D30: 2월 | E30: 314225 | F30: 기타수익 | G30: 기타 | H30: 컴투스플랫폼(기타) | I30: 2026년 2월 붕어빵 타이쿤 IP로열티 정산분 | J30: ← 컴투스 상표 로열티, 4사 공용비용 분담금
A31: 28 | B31: 주식회사 하이브로 | C31: 46081 | D31: 2월 | E31: 17227545 | F31: 기타수익 | G31: 기타 | H31: 하이브로 | I31: 01월/매출_수익정산/하이브로 타이니팜 매출 정산(2026년 01월) | J31: ← 타이니팜/드래곤럼블 매출 정산
A32: 29 | B32: 주식회사 하이브로 | C32: 46081 | D32: 2월 | E32: 4734168 | F32: 기타수익 | G32: 기타 | H32: 하이브로 | I32: 01월/매출_수익정산/하이브로 드래곤럼블 매출 정산(2026년 01월) | J32: ← 타이니팜/드래곤럼블 매출 정산
A33: 30 | B33: 주식회사 컴투스홀딩스 | C33: 46081 | D33: 2월 | E33: 11241702 | F33: 기타수익 | G33: 기타 | H33: 컴투스홀딩스(기타) | I33: [매출 / 가인식] 1월 그룹사 홍보비용 정산(홀딩스) | J33: ← 그룹사 홍보비용 정산
A34: 31 | B34: 주식회사 컴투스홀딩스 | C34: 46081 | D34: 2월 | E34: 11241702 | F34: 기타수익 | G34: 기타 | H34: 컴투스홀딩스(기타) | I34: [매출 / 가인식] 2월 그룹사 홍보비용 정산(홀딩스) | J34: ← 그룹사 홍보비용 정산
A35: 32 | B35: 주식회사 컴투스플랫폼 | C35: 46081 | D35: 2월 | E35: 4822897 | F35: 기타수익 | G35: 기타 | H35: 컴투스플랫폼(기타) | I35: [매출 / 가인식] 1월 그룹사 홍보비용 정산(플랫폼) | J35: ← 컴투스 상표 로열티, 4사 공용비용 분담금
... A59: 59 | B59: 과천펜타원 관리단 | C59: 46112 | D59: 3월 | E59: 5273300 | F59: 기타수익 | G59: 기타 | H59: 과천펜타원 관리단 | I59: 과천펜타원 공실에 다른 주차수익 | J59: 과천펜타원 공실에 따른 주차수익, 계정대체
A60: 60 | B60: (주) 공게임즈 | C60: 46112 | D60: 3월 | E60: 38159602 | F60: 기타수익 | G60: 로열티수익 | H60: 공게임즈 | I60: 3월 선수협 퍼블리시티권 정산_공게임즈_이사만루 | J60: 0
A61: 61 | B61: (주) 네오위즈스포츠 | C61: 46112 | D61: 3월 | E61: 56637702 | F61: 기타수익 | G61: 로열티수익 | H61: 네오위즈스포츠 | I61: 3월 선수협 퍼블리시티권 정산_네오위즈_슬리거(PC) | J61: 0
A62: 62 | B62: 넷마블 주식회사 | C62: 46112 | D62: 3월 | E62: 65888200 | F62: 기타수익 | G62: 기타 | H62: 넷마블(기타) | I62: 3월 선수협 퍼블리시티권 정산_넷마블_마구마구 리마스터(PC) | J62: 0
A63: 63 | B63: 넷마블 주식회사 | C63: 46112 | D63: 3월 | E63: 65377785 | F63: 기타수익 | G63: 기타 | H63: 넷마블(기타) | I63: 3월 선수협 퍼블리시티권 정산_넷마블_마구마구 | J63: 0
A64: 64 | B64: 주식회사 에이스프로젝트 | C64: 46112 | D64: 3월 | E64: 11340931 | F64: 기타수익 | G64: 로열티수익 | H64: 에이스프로젝트 | I64: 3월 선수협 퍼블리시티권 정산_에이스프로젝트_9UP프로야구 | J64: 0
...

Sheet __Lists__
A1: (전체) | B1: (전체) | C1: (전체)
A2: 1월 | B2: Admob | C2: 게임매출
A3: 2월 | B3: Amazon | C3: 기타수익
A4: 3월 | B4: Beijing Raymobile | C4: 용역수익
A5: 4월 | B5: Com2uS USA
B6: Facebook
B7: Huawei
B8: Line
B9: MetaMagnet
B10: OASYS
B11: OOTP
B12: OOTP(로열티)
B13: OOTP(용역)
B14: Paypal
B15: Red River
B16: SBTM
B17: SOFT-WORLD
... B57: 해긴
